Workbook

Sheet Inicio
A1: EXCEL MAESTRO - MANIOBRAS DE DESCARGA
A3: Objetivo | B3: Registrar maniobras, trabajadores, importes manuales, pagos pendientes y pagos realizados.
A4: Paso 1 | B4: Actualiza Criterios con productos y tarifas cuando cambien.
A5: Paso 2 | B5: Actualiza Trabajadores con la lista final y extras de referencia si aplican.
A6: Paso 3 | B6: Captura cada maniobra en Maniobras y sus participantes en Detalle_Pagos.
A7: Paso 4 | B7: Marca Pagado? como Si o No por trabajador.
A8: Paso 5 | B8: Consulta Pendientes, Resumen y Ficha para imprimir/firmar.

Sheet Criterios
A1: CRITERIOS / TARIFAS EDITABLES
A3: Producto | B3: Dentro horario | C3: Fuera horario | D3: Activo
A4: MAIZ | B4: 50 | C4: 60 | D4: Si
A5: SORGO | B5: 50 | C5: 60 | D5: Si
A6: SOYA | B6: 60 | C6: 70 | D6: Si
A7: SALVADO | B7: 40 | C7: 50 | D7: Si
A8: DDG | B8: 50 | C8: 60 | D8: Si
A9: ROLADO | B9: 40 | C9: 50 | D9: Si
A10: CALCIO | B10: 40 | C10: 50 | D10: Si

Sheet Trabajadores
A1: TRABAJADORES EDITABLES
A4: ID | B4: Trabajador | C4: Activo | D4: Extra referencia | E4: Notas
A5: 1 | B5: Carlos Salas | C5: Si | D5: 100
A6: 2 | B6: Juan | C6: Si | D6: 0
A7: 3 | B7: Uriel | C7: Si | D7: 0
A8: 4 | B8: Eliseo | C8: Si | D8: 0
A9: 5 | B9: Marcos | C9: Si | D9: 0
A10: 6 | B10: Fabián | C10: Si | D10: 0
A11: 7 | B11: Ramses | C11: Si | D11: 0
A12: 8 | B12: Emanuel | C12: Si | D12: 0
A13: 9 | B13: Ahmed | C13: Si | D13: 0
A14: 10 | B14: Juan Carlos | C14: Si | D14: 0
A15: 11 | B15: Gabriel | C15: Si | D15: 0
A16: 12 | B16: Pavel | C16: Si | D16: 0
A17: 13 | B17: Severiano | C17: Si | D17: 0

Sheet Maniobras
A1: REGISTRO DE MANIOBRAS
A4: No. maniobra | B4: Fecha | C4: Horario descarga | D4: Producto | E4: Tipo tarifa | F4: Toneladas | G4: Tarifa auto | H4: Ajuste total | I4: Total maniobra | J4: # trabajadores | K4: Importe sugerido | L4: Total manual | M4: Pendiente | N4: Estado | O4: Observaciones
G5: =IF(A5="","",IFERROR(INDEX(Criterios!$B$4:$C$83,MATCH(D5,Criterios!$A$4:$A$83,0),IF(E5="Dentro horario",1,2)),"")) | I5: =IF(A5="","",IF(OR(F5="",G5=""),"",F5*G5+N(H5))) | J5: =IF(A5="","",COUNTIF(Detalle_Pagos!$A$5:$A$2004,A5)) | K5: =IF(A5="","",IF(OR(J5=0,I5=""),"",I5/J5)) | L5: =IF(A5="","",SUMIF(Detalle_Pagos!$A$5:$A$2004,A5,Detalle_Pagos!$I$5:$I$2004)) | M5: =IF(A5="","",SUMIFS(Detalle_Pagos!$I$5:$I$2004,Detalle_Pagos!$A$5:$A$2004,A5,Detalle_Pagos!$J$5:$J$2004,"No")) | N5: =IF(A5="","",IF(J5=0,"Sin detalle",IF(M5=0,"Pagada","Pendiente")))
G6: =IF(A6="","",IFERROR(INDEX(Criterios!$B$4:$C$83,MATCH(D6,Criterios!$A$4:$A$83,0),IF(E6="Dentro horario",1,2)),"")) | I6: =IF(A6="","",IF(OR(F6="",G6=""),"",F6*G6+N(H6))) | J6: =IF(A6="","",COUNTIF(Detalle_Pagos!$A$5:$A$2004,A6)) | K6: =IF(A6="","",IF(OR(J6=0,I6=""),"",I6/J6)) | L6: =IF(A6="","",SUMIF(Detalle_Pagos!$A$5:$A$2004,A6,Detalle_Pagos!$I$5:$I$2004)) | M6: =IF(A6="","",SUMIFS(Detalle_Pagos!$I$5:$I$2004,Detalle_Pagos!$A$5:$A$2004,A6,Detalle_Pagos!$J$5:$J$2004,"No")) | N6: =IF(A6="","",IF(J6=0,"Sin detalle",IF(M6=0,"Pagada","Pendiente")))
G7: =IF(A7="","",IFERROR(INDEX(Criterios!$B$4:$C$83,MATCH(D7,Criterios!$A$4:$A$83,0),IF(E7="Dentro horario",1,2)),"")) | I7: =IF(A7="","",IF(OR(F7="",G7=""),"",F7*G7+N(H7))) | J7: =IF(A7="","",COUNTIF(Detalle_Pagos!$A$5:$A$2004,A7)) | K7: =IF(A7="","",IF(OR(J7=0,I7=""),"",I7/J7)) | L7: =IF(A7="","",SUMIF(Detalle_Pagos!$A$5:$A$2004,A7,Detalle_Pagos!$I$5:$I$2004)) | M7: =IF(A7="","",SUMIFS(Detalle_Pagos!$I$5:$I$2004,Detalle_Pagos!$A$5:$A$2004,A7,Detalle_Pagos!$J$5:$J$2004,"No")) | N7: =IF(A7="","",IF(J7=0,"Sin detalle",IF(M7=0,"Pagada","Pendiente")))
G8: =IF(A8="","",IFERROR(INDEX(Criterios!$B$4:$C$83,MATCH(D8,Criterios!$A$4:$A$83,0),IF(E8="Dentro horario",1,2)),"")) | I8: =IF(A8="","",IF(OR(F8="",G8=""),"",F8*G8+N(H8))) | J8: =IF(A8="","",COUNTIF(Detalle_Pagos!$A$5:$A$2004,A8)) | K8: =IF(A8="","",IF(OR(J8=0,I8=""),"",I8/J8)) | L8: =IF(A8="","",SUMIF(Detalle_Pagos!$A$5:$A$2004,A8,Detalle_Pagos!$I$5:$I$2004)) | M8: =IF(A8="","",SUMIFS(Detalle_Pagos!$I$5:$I$2004,Detalle_Pagos!$A$5:$A$2004,A8,Detalle_Pagos!$J$5:$J$2004,"No")) | N8: =IF(A8="","",IF(J8=0,"Sin detalle",IF(M8=0,"Pagada","Pendiente")))
G9: =IF(A9="","",IFERROR(INDEX(Criterios!$B$4:$C$83,MATCH(D9,Criterios!$A$4:$A$83,0),IF(E9="Dentro horario",1,2)),"")) | I9: =IF(A9="","",IF(OR(F9="",G9=""),"",F9*G9+N(H9))) | J9: =IF(A9="","",COUNTIF(Detalle_Pagos!$A$5:$A$2004,A9)) | K9: =IF(A9="","",IF(OR(J9=0,I9=""),"",I9/J9)) | L9: =IF(A9="","",SUMIF(Detalle_Pagos!$A$5:$A$2004,A9,Detalle_Pagos!$I$5:$I$2004)) | M9: =IF(A9="","",SUMIFS(Detalle_Pagos!$I$5:$I$2004,Detalle_Pagos!$A$5:$A$2004,A9,Detalle_Pagos!$J$5:$J$2004,"No")) | N9: =IF(A9="","",IF(J9=0,"Sin detalle",IF(M9=0,"Pagada","Pendiente")))
G10: =IF(A10="","",IFERROR(INDEX(Criterios!$B$4:$C$83,MATCH(D10,Criterios!$A$4:$A$83,0),IF(E10="Dentro horario",1,2)),"")) | I10: =IF(A10="","",IF(OR(F10="",G10=""),"",F10*G10+N(H10))) | J10: =IF(A10="","",COUNTIF(Detalle_Pagos!$A$5:$A$2004,A10)) | K10: =IF(A10="","",IF(OR(J10=0,I10=""),"",I10/J10)) | L10: =IF(A10="","",SUMIF(Detalle_Pagos!$A$5:$A$2004,A10,Detalle_Pagos!$I$5:$I$2004)) | M10: =IF(A10="","",SUMIFS(Detalle_Pagos!$I$5:$I$2004,Detalle_Pagos!$A$5:$A$2004,A10,Detalle_Pagos!$J$5:$J$2004,"No")) | N10: =IF(A10="","",IF(J10=0,"Sin detalle",IF(M10=0,"Pagada","Pendiente")))
G11: =IF(A11="","",IFERROR(INDEX(Criterios!$B$4:$C$83,MATCH(D11,Criterios!$A$4:$A$83,0),IF(E11="Dentro horario",1,2)),"")) | I11: =IF(A11="","",IF(OR(F11="",G11=""),"",F11*G11+N(H11))) | J11: =IF(A11="","",COUNTIF(Detalle_Pagos!$A$5:$A$2004,A11)) | K11: =IF(A11="","",IF(OR(J11=0,I11=""),"",I11/J11)) | L11: =IF(A11="","",SUMIF(Detalle_Pagos!$A$5:$A$2004,A11,Detalle_Pagos!$I$5:$I$2004)) | M11: =IF(A11="","",SUMIFS(Detalle_Pagos!$I$5:$I$2004,Detalle_Pagos!$A$5:$A$2004,A11,Detalle_Pagos!$J$5:$J$2004,"No")) | N11: =IF(A11="","",IF(J11=0,"Sin detalle",IF(M11=0,"Pagada","Pendiente")))
G12: =IF(A12="","",IFERROR(INDEX(Criterios!$B$4:$C$83,MATCH(D12,Criterios!$A$4:$A$83,0),IF(E12="Dentro horario",1,2)),"")) | I12: =IF(A12="","",IF(OR(F12="",G12=""),"",F12*G12+N(H12))) | J12: =IF(A12="","",COUNTIF(Detalle_Pagos!$A$5:$A$2004,A12)) | K12: =IF(A12="","",IF(OR(J12=0,I12=""),"",I12/J12)) | L12: =IF(A12="","",SUMIF(Detalle_Pagos!$A$5:$A$2004,A12,Detalle_Pagos!$I$5:$I$2004)) | M12: =IF(A12="","",SUMIFS(Detalle_Pagos!$I$5:$I$2004,Detalle_Pagos!$A$5:$A$2004,A12,Detalle_Pagos!$J$5:$J$2004,"No")) | N12: =IF(A12="","",IF(J12=0,"Sin detalle",IF(M12=0,"Pagada","Pendiente")))
G13: =IF(A13="","",IFERROR(INDEX(Criterios!$B$4:$C$83,MATCH(D13,Criterios!$A$4:$A$83,0),IF(E13="Dentro horario",1,2)),"")) | I13: =IF(A13="","",IF(OR(F13="",G13=""),"",F13*G13+N(H13))) | J13: =IF(A13="","",COUNTIF(Detalle_Pagos!$A$5:$A$2004,A13)) | K13: =IF(A13="","",IF(OR(J13=0,I13=""),"",I13/J13)) | L13: =IF(A13="","",SUMIF(Detalle_Pagos!$A$5:$A$2004,A13,Detalle_Pagos!$I$5:$I$2004)) | M13: =IF(A13="","",SUMIFS(Detalle_Pagos!$I$5:$I$2004,Detalle_Pagos!$A$5:$A$2004,A13,Detalle_Pagos!$J$5:$J$2004,"No")) | N13: =IF(A13="","",IF(J13=0,"Sin detalle",IF(M13=0,"Pagada","Pendiente")))
G14: =IF(A14="","",IFERROR(INDEX(Criterios!$B$4:$C$83,MATCH(D14,Criterios!$A$4:$A$83,0),IF(E14="Dentro horario",1,2)),"")) | I14: =IF(A14="","",IF(OR(F14="",G14=""),"",F14*G14+N(H14))) | J14: =IF(A14="","",COUNTIF(Detalle_Pagos!$A$5:$A$2004,A14)) | K14: =IF(A14="","",IF(OR(J14=0,I14=""),"",I14/J14)) | L14: =IF(A14="","",SUMIF(Detalle_Pagos!$A$5:$A$2004,A14,Detalle_Pagos!$I$5:$I$2004)) | M14: =IF(A14="","",SUMIFS(Detalle_Pagos!$I$5:$I$2004,Detalle_Pagos!$A$5:$A$2004,A14,Detalle_Pagos!$J$5:$J$2004,"No")) | N14: =IF(A14="","",IF(J14=0,"Sin detalle",IF(M14=0,"Pagada","Pendiente")))
G15: =IF(A15="","",IFERROR(INDEX(Criterios!$B$4:$C$83,MATCH(D15,Criterios!$A$4:$A$83,0),IF(E15="Dentro horario",1,2)),"")) | I15: =IF(A15="","",IF(OR(F15="",G15=""),"",F15*G15+N(H15))) | J15: =IF(A15="","",COUNTIF(Detalle_Pagos!$A$5:$A$2004,A15)) | K15: =IF(A15="","",IF(OR(J15=0,I15=""),"",I15/J15)) | L15: =IF(A15="","",SUMIF(Detalle_Pagos!$A$5:$A$2004,A15,Detalle_Pagos!$I$5:$I$2004)) | M15: =IF(A15="","",SUMIFS(Detalle_Pagos!$I$5:$I$2004,Detalle_Pagos!$A$5:$A$2004,A15,Detalle_Pagos!$J$5:$J$2004,"No")) | N15: =IF(A15="","",IF(J15=0,"Sin detalle",IF(M15=0,"Pagada","Pendiente")))
G16: =IF(A16="","",IFERROR(INDEX(Criterios!$B$4:$C$83,MATCH(D16,Criterios!$A$4:$A$83,0),IF(E16="Dentro horario",1,2)),"")) | I16: =IF(A16="","",IF(OR(F16="",G16=""),"",F16*G16+N(H16))) | J16: =IF(A16="","",COUNTIF(Detalle_Pagos!$A$5:$A$2004,A16)) | K16: =IF(A16="","",IF(OR(J16=0,I16=""),"",I16/J16)) | L16: =IF(A16="","",SUMIF(Detalle_Pagos!$A$5:$A$2004,A16,Detalle_Pagos!$I$5:$I$2004)) | M16: =IF(A16="","",SUMIFS(Detalle_Pagos!$I$5:$I$2004,Detalle_Pagos!$A$5:$A$2004,A16,Detalle_Pagos!$J$5:$J$2004,"No")) | N16: =IF(A16="","",IF(J16=0,"Sin detalle",IF(M16=0,"Pagada","Pendiente")))
... G504: =IF(A504="","",IFERROR(INDEX(Criterios!$B$4:$C$83,MATCH(D504,Criterios!$A$4:$A$83,0),IF(E504="Dentro horario",1,2)),"")) | I504: =IF(A504="","",IF(OR(F504="",G504=""),"",F504*G504+N(H504))) | J504: =IF(A504="","",COUNTIF(Detalle_Pagos!$A$5:$A$2004,A504)) | K504: =IF(A504="","",IF(OR(J504=0,I504=""),"",I504/J504)) | L504: =IF(A504="","",SUMIF(Detalle_Pagos!$A$5:$A$2004,A504,Detalle_Pagos!$I$5:$I$2004)) | M504: =IF(A504="","",SUMIFS(Detalle_Pagos!$I$5:$I$2004,Detalle_Pagos!$A$5:$A$2004,A504,Detalle_Pagos!$J$5:$J$2004,"No")) | N504: =IF(A504="","",IF(J504=0,"Sin detalle",IF(M504=0,"Pagada","Pendiente")))

Sheet Detalle_Pagos
A1: DETALLE DE PAGOS POR TRABAJADOR
A4: No. maniobra | B4: Fecha | C4: Mes | D4: Producto | E4: Trabajador | F4: Importe sugerido | G4: Importe manual | H4: Extra manual | I4: Total a pagar | J4: Pagado? | K4: Fecha cobro | L4: Notas/Firma
B5: =IF(A5="","",IFERROR(INDEX(Maniobras!$B$5:$B$504,MATCH(A5,Maniobras!$A$5:$A$504,0)),"")) | C5: =IF(B5="","",TEXT(B5,"yyyy-mm")) | D5: =IF(A5="","",IFERROR(INDEX(Maniobras!$D$5:$D$504,MATCH(A5,Maniobras!$A$5:$A$504,0)),"")) | F5: =IF(A5="","",IFERROR(INDEX(Maniobras!$K$5:$K$504,MATCH(A5,Maniobras!$A$5:$A$504,0)),"")) | I5: =IF(G5="","",G5+N(H5)) | M5: =IF($A5=Ficha!$B$3,COUNTIF($A$5:$A5,Ficha!$B$3),"")
B6: =IF(A6="","",IFERROR(INDEX(Maniobras!$B$5:$B$504,MATCH(A6,Maniobras!$A$5:$A$504,0)),"")) | C6: =IF(B6="","",TEXT(B6,"yyyy-mm")) | D6: =IF(A6="","",IFERROR(INDEX(Maniobras!$D$5:$D$504,MATCH(A6,Maniobras!$A$5:$A$504,0)),"")) | F6: =IF(A6="","",IFERROR(INDEX(Maniobras!$K$5:$K$504,MATCH(A6,Maniobras!$A$5:$A$504,0)),"")) | I6: =IF(G6="","",G6+N(H6)) | M6: =IF($A6=Ficha!$B$3,COUNTIF($A$5:$A6,Ficha!$B$3),"")
B7: =IF(A7="","",IFERROR(INDEX(Maniobras!$B$5:$B$504,MATCH(A7,Maniobras!$A$5:$A$504,0)),"")) | C7: =IF(B7="","",TEXT(B7,"yyyy-mm")) | D7: =IF(A7="","",IFERROR(INDEX(Maniobras!$D$5:$D$504,MATCH(A7,Maniobras!$A$5:$A$504,0)),"")) | F7: =IF(A7="","",IFERROR(INDEX(Maniobras!$K$5:$K$504,MATCH(A7,Maniobras!$A$5:$A$504,0)),"")) | I7: =IF(G7="","",G7+N(H7)) | M7: =IF($A7=Ficha!$B$3,COUNTIF($A$5:$A7,Ficha!$B$3),"")
B8: =IF(A8="","",IFERROR(INDEX(Maniobras!$B$5:$B$504,MATCH(A8,Maniobras!$A$5:$A$504,0)),"")) | C8: =IF(B8="","",TEXT(B8,"yyyy-mm")) | D8: =IF(A8="","",IFERROR(INDEX(Maniobras!$D$5:$D$504,MATCH(A8,Maniobras!$A$5:$A$504,0)),"")) | F8: =IF(A8="","",IFERROR(INDEX(Maniobras!$K$5:$K$504,MATCH(A8,Maniobras!$A$5:$A$504,0)),"")) | I8: =IF(G8="","",G8+N(H8)) | M8: =IF($A8=Ficha!$B$3,COUNTIF($A$5:$A8,Ficha!$B$3),"")
B9: =IF(A9="","",IFERROR(INDEX(Maniobras!$B$5:$B$504,MATCH(A9,Maniobras!$A$5:$A$504,0)),"")) | C9: =IF(B9="","",TEXT(B9,"yyyy-mm")) | D9: =IF(A9="","",IFERROR(INDEX(Maniobras!$D$5:$D$504,MATCH(A9,Maniobras!$A$5:$A$504,0)),"")) | F9: =IF(A9="","",IFERROR(INDEX(Maniobras!$K$5:$K$504,MATCH(A9,Maniobras!$A$5:$A$504,0)),"")) | I9: =IF(G9="","",G9+N(H9)) | M9: =IF($A9=Ficha!$B$3,COUNTIF($A$5:$A9,Ficha!$B$3),"")
B10: =IF(A10="","",IFERROR(INDEX(Maniobras!$B$5:$B$504,MATCH(A10,Maniobras!$A$5:$A$504,0)),"")) | C10: =IF(B10="","",TEXT(B10,"yyyy-mm")) | D10: =IF(A10="","",IFERROR(INDEX(Maniobras!$D$5:$D$504,MATCH(A10,Maniobras!$A$5:$A$504,0)),"")) | F10: =IF(A10="","",IFERROR(INDEX(Maniobras!$K$5:$K$504,MATCH(A10,Maniobras!$A$5:$A$504,0)),"")) | I10: =IF(G10="","",G10+N(H10)) | M10: =IF($A10=Ficha!$B$3,COUNTIF($A$5:$A10,Ficha!$B$3),"")
B11: =IF(A11="","",IFERROR(INDEX(Maniobras!$B$5:$B$504,MATCH(A11,Maniobras!$A$5:$A$504,0)),"")) | C11: =IF(B11="","",TEXT(B11,"yyyy-mm")) | D11: =IF(A11="","",IFERROR(INDEX(Maniobras!$D$5:$D$504,MATCH(A11,Maniobras!$A$5:$A$504,0)),"")) | F11: =IF(A11="","",IFERROR(INDEX(Maniobras!$K$5:$K$504,MATCH(A11,Maniobras!$A$5:$A$504,0)),"")) | I11: =IF(G11="","",G11+N(H11)) | M11: =IF($A11=Ficha!$B$3,COUNTIF($A$5:$A11,Ficha!$B$3),"")
B12: =IF(A12="","",IFERROR(INDEX(Maniobras!$B$5:$B$504,MATCH(A12,Maniobras!$A$5:$A$504,0)),"")) | C12: =IF(B12="","",TEXT(B12,"yyyy-mm")) | D12: =IF(A12="","",IFERROR(INDEX(Maniobras!$D$5:$D$504,MATCH(A12,Maniobras!$A$5:$A$504,0)),"")) | F12: =IF(A12="","",IFERROR(INDEX(Maniobras!$K$5:$K$504,MATCH(A12,Maniobras!$A$5:$A$504,0)),"")) | I12: =IF(G12="","",G12+N(H12)) | M12: =IF($A12=Ficha!$B$3,COUNTIF($A$5:$A12,Ficha!$B$3),"")
B13: =IF(A13="","",IFERROR(INDEX(Maniobras!$B$5:$B$504,MATCH(A13,Maniobras!$A$5:$A$504,0)),"")) | C13: =IF(B13="","",TEXT(B13,"yyyy-mm")) | D13: =IF(A13="","",IFERROR(INDEX(Maniobras!$D$5:$D$504,MATCH(A13,Maniobras!$A$5:$A$504,0)),"")) | F13: =IF(A13="","",IFERROR(INDEX(Maniobras!$K$5:$K$504,MATCH(A13,Maniobras!$A$5:$A$504,0)),"")) | I13: =IF(G13="","",G13+N(H13)) | M13: =IF($A13=Ficha!$B$3,COUNTIF($A$5:$A13,Ficha!$B$3),"")
B14: =IF(A14="","",IFERROR(INDEX(Maniobras!$B$5:$B$504,MATCH(A14,Maniobras!$A$5:$A$504,0)),"")) | C14: =IF(B14="","",TEXT(B14,"yyyy-mm")) | D14: =IF(A14="","",IFERROR(INDEX(Maniobras!$D$5:$D$504,MATCH(A14,Maniobras!$A$5:$A$504,0)),"")) | F14: =IF(A14="","",IFERROR(INDEX(Maniobras!$K$5:$K$504,MATCH(A14,Maniobras!$A$5:$A$504,0)),"")) | I14: =IF(G14="","",G14+N(H14)) | M14: =IF($A14=Ficha!$B$3,COUNTIF($A$5:$A14,Ficha!$B$3),"")
B15: =IF(A15="","",IFERROR(INDEX(Maniobras!$B$5:$B$504,MATCH(A15,Maniobras!$A$5:$A$504,0)),"")) | C15: =IF(B15="","",TEXT(B15,"yyyy-mm")) | D15: =IF(A15="","",IFERROR(INDEX(Maniobras!$D$5:$D$504,MATCH(A15,Maniobras!$A$5:$A$504,0)),"")) | F15: =IF(A15="","",IFERROR(INDEX(Maniobras!$K$5:$K$504,MATCH(A15,Maniobras!$A$5:$A$504,0)),"")) | I15: =IF(G15="","",G15+N(H15)) | M15: =IF($A15=Ficha!$B$3,COUNTIF($A$5:$A15,Ficha!$B$3),"")
B16: =IF(A16="","",IFERROR(INDEX(Maniobras!$B$5:$B$504,MATCH(A16,Maniobras!$A$5:$A$504,0)),"")) | C16: =IF(B16="","",TEXT(B16,"yyyy-mm")) | D16: =IF(A16="","",IFERROR(INDEX(Maniobras!$D$5:$D$504,MATCH(A16,Maniobras!$A$5:$A$504,0)),"")) | F16: =IF(A16="","",IFERROR(INDEX(Maniobras!$K$5:$K$504,MATCH(A16,Maniobras!$A$5:$A$504,0)),"")) | I16: =IF(G16="","",G16+N(H16)) | M16: =IF($A16=Ficha!$B$3,COUNTIF($A$5:$A16,Ficha!$B$3),"")
... B2004: =IF(A2004="","",IFERROR(INDEX(Maniobras!$B$5:$B$504,MATCH(A2004,Maniobras!$A$5:$A$504,0)),"")) | C2004: =IF(B2004="","",TEXT(B2004,"yyyy-mm")) | D2004: =IF(A2004="","",IFERROR(INDEX(Maniobras!$D$5:$D$504,MATCH(A2004,Maniobras!$A$5:$A$504,0)),"")) | F2004: =IF(A2004="","",IFERROR(INDEX(Maniobras!$K$5:$K$504,MATCH(A2004,Maniobras!$A$5:$A$504,0)),"")) | I2004: =IF(G2004="","",G2004+N(H2004)) | M2004: =IF($A2004=Ficha!$B$3,COUNTIF($A$5:$A2004,Ficha!$B$3),"")

Sheet Pendientes
A1: PENDIENTES POR TRABAJADOR
A3: Lee Detalle_Pagos y suma automaticamente los pagos marcados como No.
A7: Trabajador | B7: Maniobras pendientes | C7: Total pendiente | D7: Extra referencia | E7: Pendiente + extra ref. | F7: Ultima fecha pendiente | G7: Pagado acumulado | H7: Maniobras pagadas | J7: Trabajador | K7: Maniobras pendientes | L7: Total pendiente | M7: Extra referencia | N7: Pendiente + extra ref. | O7: Ultima fecha pendiente | P7: Pagado acumulado | Q7: Maniobras pagadas | R7: Orden
A8: =IFERROR(INDEX($J$8:$J$207,MATCH(LARGE($R$8:$R$207,ROWS($A$8:A8)),$R$8:$R$207,0)),"") | B8: =IFERROR(INDEX($K$8:$K$207,MATCH(LARGE($R$8:$R$207,ROWS($A$8:A8)),$R$8:$R$207,0)),"") | C8: =IFERROR(INDEX($L$8:$L$207,MATCH(LARGE($R$8:$R$207,ROWS($A$8:A8)),$R$8:$R$207,0)),"") | D8: =IFERROR(INDEX($M$8:$M$207,MATCH(LARGE($R$8:$R$207,ROWS($A$8:A8)),$R$8:$R$207,0)),"") | E8: =IFERROR(INDEX($N$8:$N$207,MATCH(LARGE($R$8:$R$207,ROWS($A$8:A8)),$R$8:$R$207,0)),"") | F8: =IFERROR(INDEX($O$8:$O$207,MATCH(LARGE($R$8:$R$207,ROWS($A$8:A8)),$R$8:$R$207,0)),"") | G8: =IFERROR(INDEX($P$8:$P$207,MATCH(LARGE($R$8:$R$207,ROWS($A$8:A8)),$R$8:$R$207,0)),"") | H8: =IFERROR(INDEX($Q$8:$Q$207,MATCH(LARGE($R$8:$R$207,ROWS($A$8:A8)),$R$8:$R$207,0)),"") | J8: =IF(Trabajadores!B5="","",Trabajadores!B5) | K8: =IF(J8="","",COUNTIFS(Detalle_Pagos!$E$5:$E$2004,J8,Detalle_Pagos!$J$5:$J$2004,"No")) | L8: =IF(J8="","",SUMIFS(Detalle_Pagos!$I$5:$I$2004,Detalle_Pagos!$E$5:$E$2004,J8,Detalle_Pagos!$J$5:$J$2004,"No")) | M8: =IF(J8="","",K8*IFERROR(INDEX(Trabajadores!$D$5:$D$204,MATCH(J8,Trabajadores!$B$5:$B$204,0)),0)) | N8: =IF(J8="","",L8+M8) | O8: =IF(J8="","",IF(K8=0,"",LOOKUP(2,1/((Detalle_Pagos!$E$5:$E$2004=J8)*(Detalle_Pagos!$J$5:$J$2004="No")),Detalle_Pagos!$B$5:$B$2004))) | P8: =IF(J8="","",SUMIFS(Detalle_Pagos!$I$5:$I$2004,Detalle_Pagos!$E$5:$E$2004,J8,Detalle_Pagos!$J$5:$J$2004,"Si")) | Q8: =IF(J8="","",COUNTIFS(Detalle_Pagos!$E$5:$E$2004,J8,Detalle_Pagos!$J$5:$J$2004,"Si")) | R8: =IF(J8="","",N8+K8/100000+(100000-ROW())/1000000000)
A9: =IFERROR(INDEX($J$8:$J$207,MATCH(LARGE($R$8:$R$207,ROWS($A$8:A9)),$R$8:$R$207,0)),"") | B9: =IFERROR(INDEX($K$8:$K$207,MATCH(LARGE($R$8:$R$207,ROWS($A$8:A9)),$R$8:$R$207,0)),"") | C9: =IFERROR(INDEX($L$8:$L$207,MATCH(LARGE($R$8:$R$207,ROWS($A$8:A9)),$R$8:$R$207,0)),"") | D9: =IFERROR(INDEX($M$8:$M$207,MATCH(LARGE($R$8:$R$207,ROWS($A$8:A9)),$R$8:$R$207,0)),"") | E9: =IFERROR(INDEX($N$8:$N$207,MATCH(LARGE($R$8:$R$207,ROWS($A$8:A9)),$R$8:$R$207,0)),"") | F9: =IFERROR(INDEX($O$8:$O$207,MATCH(LARGE($R$8:$R$207,ROWS($A$8:A9)),$R$8:$R$207,0)),"") | G9: =IFERROR(INDEX($P$8:$P$207,MATCH(LARGE($R$8:$R$207,ROWS($A$8:A9)),$R$8:$R$207,0)),"") | H9: =IFERROR(INDEX($Q$8:$Q$207,MATCH(LARGE($R$8:$R$207,ROWS($A$8:A9)),$R$8:$R$207,0)),"") | J9: =IF(Trabajadores!B6="","",Trabajadores!B6) | K9: =IF(J9="","",COUNTIFS(Detalle_Pagos!$E$5:$E$2004,J9,Detalle_Pagos!$J$5:$J$2004,"No")) | L9: =IF(J9="","",SUMIFS(Detalle_Pagos!$I$5:$I$2004,Detalle_Pagos!$E$5:$E$2004,J9,Detalle_Pagos!$J$5:$J$2004,"No")) | M9: =IF(J9="","",K9*IFERROR(INDEX(Trabajadores!$D$5:$D$204,MATCH(J9,Trabajadores!$B$5:$B$204,0)),0)) | N9: =IF(J9="","",L9+M9) | O9: =IF(J9="","",IF(K9=0,"",LOOKUP(2,1/((Detalle_Pagos!$E$5:$E$2004=J9)*(Detalle_Pagos!$J$5:$J$2004="No")),Detalle_Pagos!$B$5:$B$2004))) | P9: =IF(J9="","",SUMIFS(Detalle_Pagos!$I$5:$I$2004,Detalle_Pagos!$E$5:$E$2004,J9,Detalle_Pagos!$J$5:$J$2004,"Si")) | Q9: =IF(J9="","",COUNTIFS(Detalle_Pagos!$E$5:$E$2004,J9,Detalle_Pagos!$J$5:$J$2004,"Si")) | R9: =IF(J9="","",N9+K9/100000+(100000-ROW())/1000000000)
A10: =IFERROR(INDEX($J$8:$J$207,MATCH(LARGE($R$8:$R$207,ROWS($A$8:A10)),$R$8:$R$207,0)),"") | B10: =IFERROR(INDEX($K$8:$K$207,MATCH(LARGE($R$8:$R$207,ROWS($A$8:A10)),$R$8:$R$207,0)),"") | C10: =IFERROR(INDEX($L$8:$L$207,MATCH(LARGE($R$8:$R$207,ROWS($A$8:A10)),$R$8:$R$207,0)),"") | D10: =IFERROR(INDEX($M$8:$M$207,MATCH(LARGE($R$8:$R$207,ROWS($A$8:A10)),$R$8:$R$207,0)),"") | E10: =IFERROR(INDEX($N$8:$N$207,MATCH(LARGE($R$8:$R$207,ROWS($A$8:A10)),$R$8:$R$207,0)),"") | F10: =IFERROR(INDEX($O$8:$O$207,MATCH(LARGE($R$8:$R$207,ROWS($A$8:A10)),$R$8:$R$207,0)),"") | G10: =IFERROR(INDEX($P$8:$P$207,MATCH(LARGE($R$8:$R$207,ROWS($A$8:A10)),$R$8:$R$207,0)),"") | H10: =IFERROR(INDEX($Q$8:$Q$207,MATCH(LARGE($R$8:$R$207,ROWS($A$8:A10)),$R$8:$R$207,0)),"") | J10: =IF(Trabajadores!B7="","",Trabajadores!B7) | K10: =IF(J10="","",COUNTIFS(Detalle_Pagos!$E$5:$E$2004,J10,Detalle_Pagos!$J$5:$J$2004,"No")) | L10: =IF(J10="","",SUMIFS(Detalle_Pagos!$I$5:$I$2004,Detalle_Pagos!$E$5:$E$2004,J10,Detalle_Pagos!$J$5:$J$2004,"No")) | M10: =IF(J10="","",K10*IFERROR(INDEX(Trabajadores!$D$5:$D$204,MATCH(J10,Trabajadores!$B$5:$B$204,0)),0)) | N10: =IF(J10="","",L10+M10) | O10: =IF(J10="","",IF(K10=0,"",LOOKUP(2,1/((Detalle_Pagos!$E$5:$E$2004=J10)*(Detalle_Pagos!$J$5:$J$2004="No")),Detalle_Pagos!$B$5:$B$2004))) | P10: =IF(J10="","",SUMIFS(Detalle_Pagos!$I$5:$I$2004,Detalle_Pagos!$E$5:$E$2004,J10,Detalle_Pagos!$J$5:$J$2004,"Si")) | Q10: =IF(J10="","",COUNTIFS(Detalle_Pagos!$E$5:$E$2004,J10,Detalle_Pagos!$J$5:$J$2004,"Si")) | R10: =IF(J10="","",N10+K10/100000+(100000-ROW())/1000000000)
A11: =IFERROR(INDEX($J$8:$J$207,MATCH(LARGE($R$8:$R$207,ROWS($A$8:A11)),$R$8:$R$207,0)),"") | B11: =IFERROR(INDEX($K$8:$K$207,MATCH(LARGE($R$8:$R$207,ROWS($A$8:A11)),$R$8:$R$207,0)),"") | C11: =IFERROR(INDEX($L$8:$L$207,MATCH(LARGE($R$8:$R$207,ROWS($A$8:A11)),$R$8:$R$207,0)),"") | D11: =IFERROR(INDEX($M$8:$M$207,MATCH(LARGE($R$8:$R$207,ROWS($A$8:A11)),$R$8:$R$207,0)),"") | E11: =IFERROR(INDEX($N$8:$N$207,MATCH(LARGE($R$8:$R$207,ROWS($A$8:A11)),$R$8:$R$207,0)),"") | F11: =IFERROR(INDEX($O$8:$O$207,MATCH(LARGE($R$8:$R$207,ROWS($A$8:A11)),$R$8:$R$207,0)),"") | G11: =IFERROR(INDEX($P$8:$P$207,MATCH(LARGE($R$8:$R$207,ROWS($A$8:A11)),$R$8:$R$207,0)),"") | H11: =IFERROR(INDEX($Q$8:$Q$207,MATCH(LARGE($R$8:$R$207,ROWS($A$8:A11)),$R$8:$R$207,0)),"") | J11: =IF(Trabajadores!B8="","",Trabajadores!B8) | K11: =IF(J11="","",COUNTIFS(Detalle_Pagos!$E$5:$E$2004,J11,Detalle_Pagos!$J$5:$J$2004,"No")) | L11: =IF(J11="","",SUMIFS(Detalle_Pagos!$I$5:$I$2004,Detalle_Pagos!$E$5:$E$2004,J11,Detalle_Pagos!$J$5:$J$2004,"No")) | M11: =IF(J11="","",K11*IFERROR(INDEX(Trabajadores!$D$5:$D$204,MATCH(J11,Trabajadores!$B$5:$B$204,0)),0)) | N11: =IF(J11="","",L11+M11) | O11: =IF(J11="","",IF(K11=0,"",LOOKUP(2,1/((Detalle_Pagos!$E$5:$E$2004=J11)*(Detalle_Pagos!$J$5:$J$2004="No")),Detalle_Pagos!$B$5:$B$2004))) | P11: =IF(J11="","",SUMIFS(Detalle_Pagos!$I$5:$I$2004,Detalle_Pagos!$E$5:$E$2004,J11,Detalle_Pagos!$J$5:$J$2004,"Si")) | Q11: =IF(J11="","",COUNTIFS(Detalle_Pagos!$E$5:$E$2004,J11,Detalle_Pagos!$J$5:$J$2004,"Si")) | R11: =IF(J11="","",N11+K11/100000+(100000-ROW())/1000000000)
A12: =IFERROR(INDEX($J$8:$J$207,MATCH(LARGE($R$8:$R$207,ROWS($A$8:A12)),$R$8:$R$207,0)),"") | B12: =IFERROR(INDEX($K$8:$K$207,MATCH(LARGE($R$8:$R$207,ROWS($A$8:A12)),$R$8:$R$207,0)),"") | C12: =IFERROR(INDEX($L$8:$L$207,MATCH(LARGE($R$8:$R$207,ROWS($A$8:A12)),$R$8:$R$207,0)),"") | D12: =IFERROR(INDEX($M$8:$M$207,MATCH(LARGE($R$8:$R$207,ROWS($A$8:A12)),$R$8:$R$207,0)),"") | E12: =IFERROR(INDEX($N$8:$N$207,MATCH(LARGE($R$8:$R$207,ROWS($A$8:A12)),$R$8:$R$207,0)),"") | F12: =IFERROR(INDEX($O$8:$O$207,MATCH(LARGE($R$8:$R$207,ROWS($A$8:A12)),$R$8:$R$207,0)),"") | G12: =IFERROR(INDEX($P$8:$P$207,MATCH(LARGE($R$8:$R$207,ROWS($A$8:A12)),$R$8:$R$207,0)),"") | H12: =IFERROR(INDEX($Q$8:$Q$207,MATCH(LARGE($R$8:$R$207,ROWS($A$8:A12)),$R$8:$R$207,0)),"") | J12: =IF(Trabajadores!B9="","",Trabajadores!B9) | K12: =IF(J12="","",COUNTIFS(Detalle_Pagos!$E$5:$E$2004,J12,Detalle_Pagos!$J$5:$J$2004,"No")) | L12: =IF(J12="","",SUMIFS(Detalle_Pagos!$I$5:$I$2004,Detalle_Pagos!$E$5:$E$2004,J12,Detalle_Pagos!$J$5:$J$2004,"No")) | M12: =IF(J12="","",K12*IFERROR(INDEX(Trabajadores!$D$5:$D$204,MATCH(J12,Trabajadores!$B$5:$B$204,0)),0)) | N12: =IF(J12="","",L12+M12) | O12: =IF(J12="","",IF(K12=0,"",LOOKUP(2,1/((Detalle_Pagos!$E$5:$E$2004=J12)*(Detalle_Pagos!$J$5:$J$2004="No")),Detalle_Pagos!$B$5:$B$2004))) | P12: =IF(J12="","",SUMIFS(Detalle_Pagos!$I$5:$I$2004,Detalle_Pagos!$E$5:$E$2004,J12,Detalle_Pagos!$J$5:$J$2004,"Si")) | Q12: =IF(J12="","",COUNTIFS(Detalle_Pagos!$E$5:$E$2004,J12,Detalle_Pagos!$J$5:$J$2004,"Si")) | R12: =IF(J12="","",N12+K12/100000+(100000-ROW())/1000000000)
A13: =IFERROR(INDEX($J$8:$J$207,MATCH(LARGE($R$8:$R$207,ROWS($A$8:A13)),$R$8:$R$207,0)),"") | B13: =IFERROR(INDEX($K$8:$K$207,MATCH(LARGE($R$8:$R$207,ROWS($A$8:A13)),$R$8:$R$207,0)),"") | C13: =IFERROR(INDEX($L$8:$L$207,MATCH(LARGE($R$8:$R$207,ROWS($A$8:A13)),$R$8:$R$207,0)),"") | D13: =IFERROR(INDEX($M$8:$M$207,MATCH(LARGE($R$8:$R$207,ROWS($A$8:A13)),$R$8:$R$207,0)),"") | E13: =IFERROR(INDEX($N$8:$N$207,MATCH(LARGE($R$8:$R$207,ROWS($A$8:A13)),$R$8:$R$207,0)),"") | F13: =IFERROR(INDEX($O$8:$O$207,MATCH(LARGE($R$8:$R$207,ROWS($A$8:A13)),$R$8:$R$207,0)),"") | G13: =IFERROR(INDEX($P$8:$P$207,MATCH(LARGE($R$8:$R$207,ROWS($A$8:A13)),$R$8:$R$207,0)),"") | H13: =IFERROR(INDEX($Q$8:$Q$207,MATCH(LARGE($R$8:$R$207,ROWS($A$8:A13)),$R$8:$R$207,0)),"") | J13: =IF(Trabajadores!B10="","",Trabajadores!B10) | K13: =IF(J13="","",COUNTIFS(Detalle_Pagos!$E$5:$E$2004,J13,Detalle_Pagos!$J$5:$J$2004,"No")) | L13: =IF(J13="","",SUMIFS(Detalle_Pagos!$I$5:$I$2004,Detalle_Pagos!$E$5:$E$2004,J13,Detalle_Pagos!$J$5:$J$2004,"No")) | M13: =IF(J13="","",K13*IFERROR(INDEX(Trabajadores!$D$5:$D$204,MATCH(J13,Trabajadores!$B$5:$B$204,0)),0)) | N13: =IF(J13="","",L13+M13) | O13: =IF(J13="","",IF(K13=0,"",LOOKUP(2,1/((Detalle_Pagos!$E$5:$E$2004=J13)*(Detalle_Pagos!$J$5:$J$2004="No")),Detalle_Pagos!$B$5:$B$2004))) | P13: =IF(J13="","",SUMIFS(Detalle_Pagos!$I$5:$I$2004,Detalle_Pagos!$E$5:$E$2004,J13,Detalle_Pagos!$J$5:$J$2004,"Si")) | Q13: =IF(J13="","",COUNTIFS(Detalle_Pagos!$E$5:$E$2004,J13,Detalle_Pagos!$J$5:$J$2004,"Si")) | R13: =IF(J13="","",N13+K13/100000+(100000-ROW())/1000000000)
A14: =IFERROR(INDEX($J$8:$J$207,MATCH(LARGE($R$8:$R$207,ROWS($A$8:A14)),$R$8:$R$207,0)),"") | B14: =IFERROR(INDEX($K$8:$K$207,MATCH(LARGE($R$8:$R$207,ROWS($A$8:A14)),$R$8:$R$207,0)),"") | C14: =IFERROR(INDEX($L$8:$L$207,MATCH(LARGE($R$8:$R$207,ROWS($A$8:A14)),$R$8:$R$207,0)),"") | D14: =IFERROR(INDEX($M$8:$M$207,MATCH(LARGE($R$8:$R$207,ROWS($A$8:A14)),$R$8:$R$207,0)),"") | E14: =IFERROR(INDEX($N$8:$N$207,MATCH(LARGE($R$8:$R$207,ROWS($A$8:A14)),$R$8:$R$207,0)),"") | F14: =IFERROR(INDEX($O$8:$O$207,MATCH(LARGE($R$8:$R$207,ROWS($A$8:A14)),$R$8:$R$207,0)),"") | G14: =IFERROR(INDEX($P$8:$P$207,MATCH(LARGE($R$8:$R$207,ROWS($A$8:A14)),$R$8:$R$207,0)),"") | H14: =IFERROR(INDEX($Q$8:$Q$207,MATCH(LARGE($R$8:$R$207,ROWS($A$8:A14)),$R$8:$R$207,0)),"") | J14: =IF(Trabajadores!B11="","",Trabajadores!B11) | K14: =IF(J14="","",COUNTIFS(Detalle_Pagos!$E$5:$E$2004,J14,Detalle_Pagos!$J$5:$J$2004,"No")) | L14: =IF(J14="","",SUMIFS(Detalle_Pagos!$I$5:$I$2004,Detalle_Pagos!$E$5:$E$2004,J14,Detalle_Pagos!$J$5:$J$2004,"No")) | M14: =IF(J14="","",K14*IFERROR(INDEX(Trabajadores!$D$5:$D$204,MATCH(J14,Trabajadores!$B$5:$B$204,0)),0)) | N14: =IF(J14="","",L14+M14) | O14: =IF(J14="","",IF(K14=0,"",LOOKUP(2,1/((Detalle_Pagos!$E$5:$E$2004=J14)*(Detalle_Pagos!$J$5:$J$2004="No")),Detalle_Pagos!$B$5:$B$2004))) | P14: =IF(J14="","",SUMIFS(Detalle_Pagos!$I$5:$I$2004,Detalle_Pagos!$E$5:$E$2004,J14,Detalle_Pagos!$J$5:$J$2004,"Si")) | Q14: =IF(J14="","",COUNTIFS(Detalle_Pagos!$E$5:$E$2004,J14,Detalle_Pagos!$J$5:$J$2004,"Si")) | R14: =IF(J14="","",N14+K14/100000+(100000-ROW())/1000000000)
A15: =IFERROR(INDEX($J$8:$J$207,MATCH(LARGE($R$8:$R$207,ROWS($A$8:A15)),$R$8:$R$207,0)),"") | B15: =IFERROR(INDEX($K$8:$K$207,MATCH(LARGE($R$8:$R$207,ROWS($A$8:A15)),$R$8:$R$207,0)),"") | C15: =IFERROR(INDEX($L$8:$L$207,MATCH(LARGE($R$8:$R$207,ROWS($A$8:A15)),$R$8:$R$207,0)),"") | D15: =IFERROR(INDEX($M$8:$M$207,MATCH(LARGE($R$8:$R$207,ROWS($A$8:A15)),$R$8:$R$207,0)),"") | E15: =IFERROR(INDEX($N$8:$N$207,MATCH(LARGE($R$8:$R$207,ROWS($A$8:A15)),$R$8:$R$207,0)),"") | F15: =IFERROR(INDEX($O$8:$O$207,MATCH(LARGE($R$8:$R$207,ROWS($A$8:A15)),$R$8:$R$207,0)),"") | G15: =IFERROR(INDEX($P$8:$P$207,MATCH(LARGE($R$8:$R$207,ROWS($A$8:A15)),$R$8:$R$207,0)),"") | H15: =IFERROR(INDEX($Q$8:$Q$207,MATCH(LARGE($R$8:$R$207,ROWS($A$8:A15)),$R$8:$R$207,0)),"") | J15: =IF(Trabajadores!B12="","",Trabajadores!B12) | K15: =IF(J15="","",COUNTIFS(Detalle_Pagos!$E$5:$E$2004,J15,Detalle_Pagos!$J$5:$J$2004,"No")) | L15: =IF(J15="","",SUMIFS(Detalle_Pagos!$I$5:$I$2004,Detalle_Pagos!$E$5:$E$2004,J15,Detalle_Pagos!$J$5:$J$2004,"No")) | M15: =IF(J15="","",K15*IFERROR(INDEX(Trabajadores!$D$5:$D$204,MATCH(J15,Trabajadores!$B$5:$B$204,0)),0)) | N15: =IF(J15="","",L15+M15) | O15: =IF(J15="","",IF(K15=0,"",LOOKUP(2,1/((Detalle_Pagos!$E$5:$E$2004=J15)*(Detalle_Pagos!$J$5:$J$2004="No")),Detalle_Pagos!$B$5:$B$2004))) | P15: =IF(J15="","",SUMIFS(Detalle_Pagos!$I$5:$I$2004,Detalle_Pagos!$E$5:$E$2004,J15,Detalle_Pagos!$J$5:$J$2004,"Si")) | Q15: =IF(J15="","",COUNTIFS(Detalle_Pagos!$E$5:$E$2004,J15,Detalle_Pagos!$J$5:$J$2004,"Si")) | R15: =IF(J15="","",N15+K15/100000+(100000-ROW())/1000000000)
A16: =IFERROR(INDEX($J$8:$J$207,MATCH(LARGE($R$8:$R$207,ROWS($A$8:A16)),$R$8:$R$207,0)),"") | B16: =IFERROR(INDEX($K$8:$K$207,MATCH(LARGE($R$8:$R$207,ROWS($A$8:A16)),$R$8:$R$207,0)),"") | C16: =IFERROR(INDEX($L$8:$L$207,MATCH(LARGE($R$8:$R$207,ROWS($A$8:A16)),$R$8:$R$207,0)),"") | D16: =IFERROR(INDEX($M$8:$M$207,MATCH(LARGE($R$8:$R$207,ROWS($A$8:A16)),$R$8:$R$207,0)),"") | E16: =IFERROR(INDEX($N$8:$N$207,MATCH(LARGE($R$8:$R$207,ROWS($A$8:A16)),$R$8:$R$207,0)),"") | F16: =IFERROR(INDEX($O$8:$O$207,MATCH(LARGE($R$8:$R$207,ROWS($A$8:A16)),$R$8:$R$207,0)),"") | G16: =IFERROR(INDEX($P$8:$P$207,MATCH(LARGE($R$8:$R$207,ROWS($A$8:A16)),$R$8:$R$207,0)),"") | H16: =IFERROR(INDEX($Q$8:$Q$207,MATCH(LARGE($R$8:$R$207,ROWS($A$8:A16)),$R$8:$R$207,0)),"") | J16: =IF(Trabajadores!B13="","",Trabajadores!B13) | K16: =IF(J16="","",COUNTIFS(Detalle_Pagos!$E$5:$E$2004,J16,Detalle_Pagos!$J$5:$J$2004,"No")) | L16: =IF(J16="","",SUMIFS(Detalle_Pagos!$I$5:$I$2004,Detalle_Pagos!$E$5:$E$2004,J16,Detalle_Pagos!$J$5:$J$2004,"No")) | M16: =IF(J16="","",K16*IFERROR(INDEX(Trabajadores!$D$5:$D$204,MATCH(J16,Trabajadores!$B$5:$B$204,0)),0)) | N16: =IF(J16="","",L16+M16) | O16: =IF(J16="","",IF(K16=0,"",LOOKUP(2,1/((Detalle_Pagos!$E$5:$E$2004=J16)*(Detalle_Pagos!$J$5:$J$2004="No")),Detalle_Pagos!$B$5:$B$2004))) | P16: =IF(J16="","",SUMIFS(Detalle_Pagos!$I$5:$I$2004,Detalle_Pagos!$E$5:$E$2004,J16,Detalle_Pagos!$J$5:$J$2004,"Si")) | Q16: =IF(J16="","",COUNTIFS(Detalle_Pagos!$E$5:$E$2004,J16,Detalle_Pagos!$J$5:$J$2004,"Si")) | R16: =IF(J16="","",N16+K16/100000+(100000-ROW())/1000000000)
A17: =IFERROR(INDEX($J$8:$J$207,MATCH(LARGE($R$8:$R$207,ROWS($A$8:A17)),$R$8:$R$207,0)),"") | B17: =IFERROR(INDEX($K$8:$K$207,MATCH(LARGE($R$8:$R$207,ROWS($A$8:A17)),$R$8:$R$207,0)),"") | C17: =IFERROR(INDEX($L$8:$L$207,MATCH(LARGE($R$8:$R$207,ROWS($A$8:A17)),$R$8:$R$207,0)),"") | D17: =IFERROR(INDEX($M$8:$M$207,MATCH(LARGE($R$8:$R$207,ROWS($A$8:A17)),$R$8:$R$207,0)),"") | E17: =IFERROR(INDEX($N$8:$N$207,MATCH(LARGE($R$8:$R$207,ROWS($A$8:A17)),$R$8:$R$207,0)),"") | F17: =IFERROR(INDEX($O$8:$O$207,MATCH(LARGE($R$8:$R$207,ROWS($A$8:A17)),$R$8:$R$207,0)),"") | G17: =IFERROR(INDEX($P$8:$P$207,MATCH(LARGE($R$8:$R$207,ROWS($A$8:A17)),$R$8:$R$207,0)),"") | H17: =IFERROR(INDEX($Q$8:$Q$207,MATCH(LARGE($R$8:$R$207,ROWS($A$8:A17)),$R$8:$R$207,0)),"") | J17: =IF(Trabajadores!B14="","",Trabajadores!B14) | K17: =IF(J17="","",COUNTIFS(Detalle_Pagos!$E$5:$E$2004,J17,Detalle_Pagos!$J$5:$J$2004,"No")) | L17: =IF(J17="","",SUMIFS(Detalle_Pagos!$I$5:$I$2004,Detalle_Pagos!$E$5:$E$2004,J17,Detalle_Pagos!$J$5:$J$2004,"No")) | M17: =IF(J17="","",K17*IFERROR(INDEX(Trabajadores!$D$5:$D$204,MATCH(J17,Trabajadores!$B$5:$B$204,0)),0)) | N17: =IF(J17="","",L17+M17) | O17: =IF(J17="","",IF(K17=0,"",LOOKUP(2,1/((Detalle_Pagos!$E$5:$E$2004=J17)*(Detalle_Pagos!$J$5:$J$2004="No")),Detalle_Pagos!$B$5:$B$2004))) | P17: =IF(J17="","",SUMIFS(Detalle_Pagos!$I$5:$I$2004,Detalle_Pagos!$E$5:$E$2004,J17,Detalle_Pagos!$J$5:$J$2004,"Si")) | Q17: =IF(J17="","",COUNTIFS(Detalle_Pagos!$E$5:$E$2004,J17,Detalle_Pagos!$J$5:$J$2004,"Si")) | R17: =IF(J17="","",N17+K17/100000+(100000-ROW())/1000000000)
A18: =IFERROR(INDEX($J$8:$J$207,MATCH(LARGE($R$8:$R$207,ROWS($A$8:A18)),$R$8:$R$207,0)),"") | B18: =IFERROR(INDEX($K$8:$K$207,MATCH(LARGE($R$8:$R$207,ROWS($A$8:A18)),$R$8:$R$207,0)),"") | C18: =IFERROR(INDEX($L$8:$L$207,MATCH(LARGE($R$8:$R$207,ROWS($A$8:A18)),$R$8:$R$207,0)),"") | D18: =IFERROR(INDEX($M$8:$M$207,MATCH(LARGE($R$8:$R$207,ROWS($A$8:A18)),$R$8:$R$207,0)),"") | E18: =IFERROR(INDEX($N$8:$N$207,MATCH(LARGE($R$8:$R$207,ROWS($A$8:A18)),$R$8:$R$207,0)),"") | F18: =IFERROR(INDEX($O$8:$O$207,MATCH(LARGE($R$8:$R$207,ROWS($A$8:A18)),$R$8:$R$207,0)),"") | G18: =IFERROR(INDEX($P$8:$P$207,MATCH(LARGE($R$8:$R$207,ROWS($A$8:A18)),$R$8:$R$207,0)),"") | H18: =IFERROR(INDEX($Q$8:$Q$207,MATCH(LARGE($R$8:$R$207,ROWS($A$8:A18)),$R$8:$R$207,0)),"") | J18: =IF(Trabajadores!B15="","",Trabajadores!B15) | K18: =IF(J18="","",COUNTIFS(Detalle_Pagos!$E$5:$E$2004,J18,Detalle_Pagos!$J$5:$J$2004,"No")) | L18: =IF(J18="","",SUMIFS(Detalle_Pagos!$I$5:$I$2004,Detalle_Pagos!$E$5:$E$2004,J18,Detalle_Pagos!$J$5:$J$2004,"No")) | M18: =IF(J18="","",K18*IFERROR(INDEX(Trabajadores!$D$5:$D$204,MATCH(J18,Trabajadores!$B$5:$B$204,0)),0)) | N18: =IF(J18="","",L18+M18) | O18: =IF(J18="","",IF(K18=0,"",LOOKUP(2,1/((Detalle_Pagos!$E$5:$E$2004=J18)*(Detalle_Pagos!$J$5:$J$2004="No")),Detalle_Pagos!$B$5:$B$2004))) | P18: =IF(J18="","",SUMIFS(Detalle_Pagos!$I$5:$I$2004,Detalle_Pagos!$E$5:$E$2004,J18,Detalle_Pagos!$J$5:$J$2004,"Si")) | Q18: =IF(J18="","",COUNTIFS(Detalle_Pagos!$E$5:$E$2004,J18,Detalle_Pagos!$J$5:$J$2004,"Si")) | R18: =IF(J18="","",N18+K18/100000+(100000-ROW())/1000000000)
A19: =IFERROR(INDEX($J$8:$J$207,MATCH(LARGE($R$8:$R$207,ROWS($A$8:A19)),$R$8:$R$207,0)),"") | B19: =IFERROR(INDEX($K$8:$K$207,MATCH(LARGE($R$8:$R$207,ROWS($A$8:A19)),$R$8:$R$207,0)),"") | C19: =IFERROR(INDEX($L$8:$L$207,MATCH(LARGE($R$8:$R$207,ROWS($A$8:A19)),$R$8:$R$207,0)),"") | D19: =IFERROR(INDEX($M$8:$M$207,MATCH(LARGE($R$8:$R$207,ROWS($A$8:A19)),$R$8:$R$207,0)),"") | E19: =IFERROR(INDEX($N$8:$N$207,MATCH(LARGE($R$8:$R$207,ROWS($A$8:A19)),$R$8:$R$207,0)),"") | F19: =IFERROR(INDEX($O$8:$O$207,MATCH(LARGE($R$8:$R$207,ROWS($A$8:A19)),$R$8:$R$207,0)),"") | G19: =IFERROR(INDEX($P$8:$P$207,MATCH(LARGE($R$8:$R$207,ROWS($A$8:A19)),$R$8:$R$207,0)),"") | H19: =IFERROR(INDEX($Q$8:$Q$207,MATCH(LARGE($R$8:$R$207,ROWS($A$8:A19)),$R$8:$R$207,0)),"") | J19: =IF(Trabajadores!B16="","",Trabajadores!B16) | K19: =IF(J19="","",COUNTIFS(Detalle_Pagos!$E$5:$E$2004,J19,Detalle_Pagos!$J$5:$J$2004,"No")) | L19: =IF(J19="","",SUMIFS(Detalle_Pagos!$I$5:$I$2004,Detalle_Pagos!$E$5:$E$2004,J19,Detalle_Pagos!$J$5:$J$2004,"No")) | M19: =IF(J19="","",K19*IFERROR(INDEX(Trabajadores!$D$5:$D$204,MATCH(J19,Trabajadores!$B$5:$B$204,0)),0)) | N19: =IF(J19="","",L19+M19) | O19: =IF(J19="","",IF(K19=0,"",LOOKUP(2,1/((Detalle_Pagos!$E$5:$E$2004=J19)*(Detalle_Pagos!$J$5:$J$2004="No")),Detalle_Pagos!$B$5:$B$2004))) | P19: =IF(J19="","",SUMIFS(Detalle_Pagos!$I$5:$I$2004,Detalle_Pagos!$E$5:$E$2004,J19,Detalle_Pagos!$J$5:$J$2004,"Si")) | Q19: =IF(J19="","",COUNTIFS(Detalle_Pagos!$E$5:$E$2004,J19,Detalle_Pagos!$J$5:$J$2004,"Si")) | R19: =IF(J19="","",N19+K19/100000+(100000-ROW())/1000000000)
... A207: =IFERROR(INDEX($J$8:$J$207,MATCH(LARGE($R$8:$R$207,ROWS($A$8:A207)),$R$8:$R$207,0)),"") | B207: =IFERROR(INDEX($K$8:$K$207,MATCH(LARGE($R$8:$R$207,ROWS($A$8:A207)),$R$8:$R$207,0)),"") | C207: =IFERROR(INDEX($L$8:$L$207,MATCH(LARGE($R$8:$R$207,ROWS($A$8:A207)),$R$8:$R$207,0)),"") | D207: =IFERROR(INDEX($M$8:$M$207,MATCH(LARGE($R$8:$R$207,ROWS($A$8:A207)),$R$8:$R$207,0)),"") | E207: =IFERROR(INDEX($N$8:$N$207,MATCH(LARGE($R$8:$R$207,ROWS($A$8:A207)),$R$8:$R$207,0)),"") | F207: =IFERROR(INDEX($O$8:$O$207,MATCH(LARGE($R$8:$R$207,ROWS($A$8:A207)),$R$8:$R$207,0)),"") | G207: =IFERROR(INDEX($P$8:$P$207,MATCH(LARGE($R$8:$R$207,ROWS($A$8:A207)),$R$8:$R$207,0)),"") | H207: =IFERROR(INDEX($Q$8:$Q$207,MATCH(LARGE($R$8:$R$207,ROWS($A$8:A207)),$R$8:$R$207,0)),"") | J207: =IF(Trabajadores!B204="","",Trabajadores!B204) | K207: =IF(J207="","",COUNTIFS(Detalle_Pagos!$E$5:$E$2004,J207,Detalle_Pagos!$J$5:$J$2004,"No")) | L207: =IF(J207="","",SUMIFS(Detalle_Pagos!$I$5:$I$2004,Detalle_Pagos!$E$5:$E$2004,J207,Detalle_Pagos!$J$5:$J$2004,"No")) | M207: =IF(J207="","",K207*IFERROR(INDEX(Trabajadores!$D$5:$D$204,MATCH(J207,Trabajadores!$B$5:$B$204,0)),0)) | N207: =IF(J207="","",L207+M207) | O207: =IF(J207="","",IF(K207=0,"",LOOKUP(2,1/((Detalle_Pagos!$E$5:$E$2004=J207)*(Detalle_Pagos!$J$5:$J$2004="No")),Detalle_Pagos!$B$5:$B$2004))) | P207: =IF(J207="","",SUMIFS(Detalle_Pagos!$I$5:$I$2004,Detalle_Pagos!$E$5:$E$2004,J207,Detalle_Pagos!$J$5:$J$2004,"Si")) | Q207: =IF(J207="","",COUNTIFS(Detalle_Pagos!$E$5:$E$2004,J207,Detalle_Pagos!$J$5:$J$2004,"Si")) | R207: =IF(J207="","",N207+K207/100000+(100000-ROW())/1000000000)

Sheet Resumen
A1: RESUMEN GENERAL Y FILTRO POR FECHAS
A3: Fecha inicio | B3: 46023 | D3: Total pagado | E3: =SUMIFS(Detalle_Pagos!$I$5:$I$2004,Detalle_Pagos!$J$5:$J$2004,"Si",Detalle_Pagos!$B$5:$B$2004,">="&$B$3,Detalle_Pagos!$B$5:$B$2004,"<="&$B$4) | G3: Maniobras registradas | H3: =COUNTIFS(Maniobras!$A$5:$A$504,"<>",Maniobras!$B$5:$B$504,">="&$B$3,Maniobras!$B$5:$B$504,"<="&$B$4)
A4: Fecha fin | B4: 46387 | D4: Total pendiente | E4: =SUMIFS(Detalle_Pagos!$I$5:$I$2004,Detalle_Pagos!$J$5:$J$2004,"No",Detalle_Pagos!$B$5:$B$2004,">="&$B$3,Detalle_Pagos!$B$5:$B$2004,"<="&$B$4) | G4: Trabajadores con pendiente | H4: =COUNTIF(Pendientes!$B$8:$B$207,">0")
A7: Trabajador | B7: Maniobras en rango | C7: Pagado en rango | D7: Pendiente en rango | E7: # pendientes | F7: # pagadas | G7: Extra ref. pendientes | H7: Total + extra ref. | I7: Total general | K7: Trabajador | L7: Maniobras en rango | M7: Pagado en rango | N7: Pendiente en rango | O7: # pendientes | P7: # pagadas | Q7: Extra ref. pendientes | R7: Total + extra ref. | S7: Total general | T7: Orden
A8: =IFERROR(INDEX($K$8:$K$207,MATCH(LARGE($T$8:$T$207,ROWS($A$8:A8)),$T$8:$T$207,0)),"") | B8: =IFERROR(INDEX($L$8:$L$207,MATCH(LARGE($T$8:$T$207,ROWS($A$8:A8)),$T$8:$T$207,0)),"") | C8: =IFERROR(INDEX($M$8:$M$207,MATCH(LARGE($T$8:$T$207,ROWS($A$8:A8)),$T$8:$T$207,0)),"") | D8: =IFERROR(INDEX($N$8:$N$207,MATCH(LARGE($T$8:$T$207,ROWS($A$8:A8)),$T$8:$T$207,0)),"") | E8: =IFERROR(INDEX($O$8:$O$207,MATCH(LARGE($T$8:$T$207,ROWS($A$8:A8)),$T$8:$T$207,0)),"") | F8: =IFERROR(INDEX($P$8:$P$207,MATCH(LARGE($T$8:$T$207,ROWS($A$8:A8)),$T$8:$T$207,0)),"") | G8: =IFERROR(INDEX($Q$8:$Q$207,MATCH(LARGE($T$8:$T$207,ROWS($A$8:A8)),$T$8:$T$207,0)),"") | H8: =IFERROR(INDEX($R$8:$R$207,MATCH(LARGE($T$8:$T$207,ROWS($A$8:A8)),$T$8:$T$207,0)),"") | I8: =IFERROR(INDEX($S$8:$S$207,MATCH(LARGE($T$8:$T$207,ROWS($A$8:A8)),$T$8:$T$207,0)),"") | K8: =IF(Trabajadores!B5="","",Trabajadores!B5) | L8: =IF(K8="","",COUNTIFS(Detalle_Pagos!$E$5:$E$2004,K8,Detalle_Pagos!$B$5:$B$2004,">="&$B$3,Detalle_Pagos!$B$5:$B$2004,"<="&$B$4)) | M8: =IF(K8="","",SUMIFS(Detalle_Pagos!$I$5:$I$2004,Detalle_Pagos!$E$5:$E$2004,K8,Detalle_Pagos!$J$5:$J$2004,"Si",Detalle_Pagos!$B$5:$B$2004,">="&$B$3,Detalle_Pagos!$B$5:$B$2004,"<="&$B$4)) | N8: =IF(K8="","",SUMIFS(Detalle_Pagos!$I$5:$I$2004,Detalle_Pagos!$E$5:$E$2004,K8,Detalle_Pagos!$J$5:$J$2004,"No",Detalle_Pagos!$B$5:$B$2004,">="&$B$3,Detalle_Pagos!$B$5:$B$2004,"<="&$B$4)) | O8: =IF(K8="","",COUNTIFS(Detalle_Pagos!$E$5:$E$2004,K8,Detalle_Pagos!$J$5:$J$2004,"No",Detalle_Pagos!$B$5:$B$2004,">="&$B$3,Detalle_Pagos!$B$5:$B$2004,"<="&$B$4)) | P8: =IF(K8="","",COUNTIFS(Detalle_Pagos!$E$5:$E$2004,K8,Detalle_Pagos!$J$5:$J$2004,"Si",Detalle_Pagos!$B$5:$B$2004,">="&$B$3,Detalle_Pagos!$B$5:$B$2004,"<="&$B$4)) | Q8: =IF(K8="","",O8*IFERROR(INDEX(Trabajadores!$D$5:$D$204,MATCH(K8,Trabajadores!$B$5:$B$204,0)),0)) | R8: =IF(K8="","",N8+Q8) | S8: =IF(K8="","",M8+N8) | T8: =IF(K8="","",S8+R8/100000+L8/100000000+(100000-ROW())/1000000000)
A9: =IFERROR(INDEX($K$8:$K$207,MATCH(LARGE($T$8:$T$207,ROWS($A$8:A9)),$T$8:$T$207,0)),"") | B9: =IFERROR(INDEX($L$8:$L$207,MATCH(LARGE($T$8:$T$207,ROWS($A$8:A9)),$T$8:$T$207,0)),"") | C9: =IFERROR(INDEX($M$8:$M$207,MATCH(LARGE($T$8:$T$207,ROWS($A$8:A9)),$T$8:$T$207,0)),"") | D9: =IFERROR(INDEX($N$8:$N$207,MATCH(LARGE($T$8:$T$207,ROWS($A$8:A9)),$T$8:$T$207,0)),"") | E9: =IFERROR(INDEX($O$8:$O$207,MATCH(LARGE($T$8:$T$207,ROWS($A$8:A9)),$T$8:$T$207,0)),"") | F9: =IFERROR(INDEX($P$8:$P$207,MATCH(LARGE($T$8:$T$207,ROWS($A$8:A9)),$T$8:$T$207,0)),"") | G9: =IFERROR(INDEX($Q$8:$Q$207,MATCH(LARGE($T$8:$T$207,ROWS($A$8:A9)),$T$8:$T$207,0)),"") | H9: =IFERROR(INDEX($R$8:$R$207,MATCH(LARGE($T$8:$T$207,ROWS($A$8:A9)),$T$8:$T$207,0)),"") | I9: =IFERROR(INDEX($S$8:$S$207,MATCH(LARGE($T$8:$T$207,ROWS($A$8:A9)),$T$8:$T$207,0)),"") | K9: =IF(Trabajadores!B6="","",Trabajadores!B6) | L9: =IF(K9="","",COUNTIFS(Detalle_Pagos!$E$5:$E$2004,K9,Detalle_Pagos!$B$5:$B$2004,">="&$B$3,Detalle_Pagos!$B$5:$B$2004,"<="&$B$4)) | M9: =IF(K9="","",SUMIFS(Detalle_Pagos!$I$5:$I$2004,Detalle_Pagos!$E$5:$E$2004,K9,Detalle_Pagos!$J$5:$J$2004,"Si",Detalle_Pagos!$B$5:$B$2004,">="&$B$3,Detalle_Pagos!$B$5:$B$2004,"<="&$B$4)) | N9: =IF(K9="","",SUMIFS(Detalle_Pagos!$I$5:$I$2004,Detalle_Pagos!$E$5:$E$2004,K9,Detalle_Pagos!$J$5:$J$2004,"No",Detalle_Pagos!$B$5:$B$2004,">="&$B$3,Detalle_Pagos!$B$5:$B$2004,"<="&$B$4)) | O9: =IF(K9="","",COUNTIFS(Detalle_Pagos!$E$5:$E$2004,K9,Detalle_Pagos!$J$5:$J$2004,"No",Detalle_Pagos!$B$5:$B$2004,">="&$B$3,Detalle_Pagos!$B$5:$B$2004,"<="&$B$4)) | P9: =IF(K9="","",COUNTIFS(Detalle_Pagos!$E$5:$E$2004,K9,Detalle_Pagos!$J$5:$J$2004,"Si",Detalle_Pagos!$B$5:$B$2004,">="&$B$3,Detalle_Pagos!$B$5:$B$2004,"<="&$B$4)) | Q9: =IF(K9="","",O9*IFERROR(INDEX(Trabajadores!$D$5:$D$204,MATCH(K9,Trabajadores!$B$5:$B$204,0)),0)) | R9: =IF(K9="","",N9+Q9) | S9: =IF(K9="","",M9+N9) | T9: =IF(K9="","",S9+R9/100000+L9/100000000+(100000-ROW())/1000000000)
A10: =IFERROR(INDEX($K$8:$K$207,MATCH(LARGE($T$8:$T$207,ROWS($A$8:A10)),$T$8:$T$207,0)),"") | B10: =IFERROR(INDEX($L$8:$L$207,MATCH(LARGE($T$8:$T$207,ROWS($A$8:A10)),$T$8:$T$207,0)),"") | C10: =IFERROR(INDEX($M$8:$M$207,MATCH(LARGE($T$8:$T$207,ROWS($A$8:A10)),$T$8:$T$207,0)),"") | D10: =IFERROR(INDEX($N$8:$N$207,MATCH(LARGE($T$8:$T$207,ROWS($A$8:A10)),$T$8:$T$207,0)),"") | E10: =IFERROR(INDEX($O$8:$O$207,MATCH(LARGE($T$8:$T$207,ROWS($A$8:A10)),$T$8:$T$207,0)),"") | F10: =IFERROR(INDEX($P$8:$P$207,MATCH(LARGE($T$8:$T$207,ROWS($A$8:A10)),$T$8:$T$207,0)),"") | G10: =IFERROR(INDEX($Q$8:$Q$207,MATCH(LARGE($T$8:$T$207,ROWS($A$8:A10)),$T$8:$T$207,0)),"") | H10: =IFERROR(INDEX($R$8:$R$207,MATCH(LARGE($T$8:$T$207,ROWS($A$8:A10)),$T$8:$T$207,0)),"") | I10: =IFERROR(INDEX($S$8:$S$207,MATCH(LARGE($T$8:$T$207,ROWS($A$8:A10)),$T$8:$T$207,0)),"") | K10: =IF(Trabajadores!B7="","",Trabajadores!B7) | L10: =IF(K10="","",COUNTIFS(Detalle_Pagos!$E$5:$E$2004,K10,Detalle_Pagos!$B$5:$B$2004,">="&$B$3,Detalle_Pagos!$B$5:$B$2004,"<="&$B$4)) | M10: =IF(K10="","",SUMIFS(Detalle_Pagos!$I$5:$I$2004,Detalle_Pagos!$E$5:$E$2004,K10,Detalle_Pagos!$J$5:$J$2004,"Si",Detalle_Pagos!$B$5:$B$2004,">="&$B$3,Detalle_Pagos!$B$5:$B$2004,"<="&$B$4)) | N10: =IF(K10="","",SUMIFS(Detalle_Pagos!$I$5:$I$2004,Detalle_Pagos!$E$5:$E$2004,K10,Detalle_Pagos!$J$5:$J$2004,"No",Detalle_Pagos!$B$5:$B$2004,">="&$B$3,Detalle_Pagos!$B$5:$B$2004,"<="&$B$4)) | O10: =IF(K10="","",COUNTIFS(Detalle_Pagos!$E$5:$E$2004,K10,Detalle_Pagos!$J$5:$J$2004,"No",Detalle_Pagos!$B$5:$B$2004,">="&$B$3,Detalle_Pagos!$B$5:$B$2004,"<="&$B$4)) | P10: =IF(K10="","",COUNTIFS(Detalle_Pagos!$E$5:$E$2004,K10,Detalle_Pagos!$J$5:$J$2004,"Si",Detalle_Pagos!$B$5:$B$2004,">="&$B$3,Detalle_Pagos!$B$5:$B$2004,"<="&$B$4)) | Q10: =IF(K10="","",O10*IFERROR(INDEX(Trabajadores!$D$5:$D$204,MATCH(K10,Trabajadores!$B$5:$B$204,0)),0)) | R10: =IF(K10="","",N10+Q10) | S10: =IF(K10="","",M10+N10) | T10: =IF(K10="","",S10+R10/100000+L10/100000000+(100000-ROW())/1000000000)
A11: =IFERROR(INDEX($K$8:$K$207,MATCH(LARGE($T$8:$T$207,ROWS($A$8:A11)),$T$8:$T$207,0)),"") | B11: =IFERROR(INDEX($L$8:$L$207,MATCH(LARGE($T$8:$T$207,ROWS($A$8:A11)),$T$8:$T$207,0)),"") | C11: =IFERROR(INDEX($M$8:$M$207,MATCH(LARGE($T$8:$T$207,ROWS($A$8:A11)),$T$8:$T$207,0)),"") | D11: =IFERROR(INDEX($N$8:$N$207,MATCH(LARGE($T$8:$T$207,ROWS($A$8:A11)),$T$8:$T$207,0)),"") | E11: =IFERROR(INDEX($O$8:$O$207,MATCH(LARGE($T$8:$T$207,ROWS($A$8:A11)),$T$8:$T$207,0)),"") | F11: =IFERROR(INDEX($P$8:$P$207,MATCH(LARGE($T$8:$T$207,ROWS($A$8:A11)),$T$8:$T$207,0)),"") | G11: =IFERROR(INDEX($Q$8:$Q$207,MATCH(LARGE($T$8:$T$207,ROWS($A$8:A11)),$T$8:$T$207,0)),"") | H11: =IFERROR(INDEX($R$8:$R$207,MATCH(LARGE($T$8:$T$207,ROWS($A$8:A11)),$T$8:$T$207,0)),"") | I11: =IFERROR(INDEX($S$8:$S$207,MATCH(LARGE($T$8:$T$207,ROWS($A$8:A11)),$T$8:$T$207,0)),"") | K11: =IF(Trabajadores!B8="","",Trabajadores!B8) | L11: =IF(K11="","",COUNTIFS(Detalle_Pagos!$E$5:$E$2004,K11,Detalle_Pagos!$B$5:$B$2004,">="&$B$3,Detalle_Pagos!$B$5:$B$2004,"<="&$B$4)) | M11: =IF(K11="","",SUMIFS(Detalle_Pagos!$I$5:$I$2004,Detalle_Pagos!$E$5:$E$2004,K11,Detalle_Pagos!$J$5:$J$2004,"Si",Detalle_Pagos!$B$5:$B$2004,">="&$B$3,Detalle_Pagos!$B$5:$B$2004,"<="&$B$4)) | N11: =IF(K11="","",SUMIFS(Detalle_Pagos!$I$5:$I$2004,Detalle_Pagos!$E$5:$E$2004,K11,Detalle_Pagos!$J$5:$J$2004,"No",Detalle_Pagos!$B$5:$B$2004,">="&$B$3,Detalle_Pagos!$B$5:$B$2004,"<="&$B$4)) | O11: =IF(K11="","",COUNTIFS(Detalle_Pagos!$E$5:$E$2004,K11,Detalle_Pagos!$J$5:$J$2004,"No",Detalle_Pagos!$B$5:$B$2004,">="&$B$3,Detalle_Pagos!$B$5:$B$2004,"<="&$B$4)) | P11: =IF(K11="","",COUNTIFS(Detalle_Pagos!$E$5:$E$2004,K11,Detalle_Pagos!$J$5:$J$2004,"Si",Detalle_Pagos!$B$5:$B$2004,">="&$B$3,Detalle_Pagos!$B$5:$B$2004,"<="&$B$4)) | Q11: =IF(K11="","",O11*IFERROR(INDEX(Trabajadores!$D$5:$D$204,MATCH(K11,Trabajadores!$B$5:$B$204,0)),0)) | R11: =IF(K11="","",N11+Q11) | S11: =IF(K11="","",M11+N11) | T11: =IF(K11="","",S11+R11/100000+L11/100000000+(100000-ROW())/1000000000)
A12: =IFERROR(INDEX($K$8:$K$207,MATCH(LARGE($T$8:$T$207,ROWS($A$8:A12)),$T$8:$T$207,0)),"") | B12: =IFERROR(INDEX($L$8:$L$207,MATCH(LARGE($T$8:$T$207,ROWS($A$8:A12)),$T$8:$T$207,0)),"") | C12: =IFERROR(INDEX($M$8:$M$207,MATCH(LARGE($T$8:$T$207,ROWS($A$8:A12)),$T$8:$T$207,0)),"") | D12: =IFERROR(INDEX($N$8:$N$207,MATCH(LARGE($T$8:$T$207,ROWS($A$8:A12)),$T$8:$T$207,0)),"") | E12: =IFERROR(INDEX($O$8:$O$207,MATCH(LARGE($T$8:$T$207,ROWS($A$8:A12)),$T$8:$T$207,0)),"") | F12: =IFERROR(INDEX($P$8:$P$207,MATCH(LARGE($T$8:$T$207,ROWS($A$8:A12)),$T$8:$T$207,0)),"") | G12: =IFERROR(INDEX($Q$8:$Q$207,MATCH(LARGE($T$8:$T$207,ROWS($A$8:A12)),$T$8:$T$207,0)),"") | H12: =IFERROR(INDEX($R$8:$R$207,MATCH(LARGE($T$8:$T$207,ROWS($A$8:A12)),$T$8:$T$207,0)),"") | I12: =IFERROR(INDEX($S$8:$S$207,MATCH(LARGE($T$8:$T$207,ROWS($A$8:A12)),$T$8:$T$207,0)),"") | K12: =IF(Trabajadores!B9="","",Trabajadores!B9) | L12: =IF(K12="","",COUNTIFS(Detalle_Pagos!$E$5:$E$2004,K12,Detalle_Pagos!$B$5:$B$2004,">="&$B$3,Detalle_Pagos!$B$5:$B$2004,"<="&$B$4)) | M12: =IF(K12="","",SUMIFS(Detalle_Pagos!$I$5:$I$2004,Detalle_Pagos!$E$5:$E$2004,K12,Detalle_Pagos!$J$5:$J$2004,"Si",Detalle_Pagos!$B$5:$B$2004,">="&$B$3,Detalle_Pagos!$B$5:$B$2004,"<="&$B$4)) | N12: =IF(K12="","",SUMIFS(Detalle_Pagos!$I$5:$I$2004,Detalle_Pagos!$E$5:$E$2004,K12,Detalle_Pagos!$J$5:$J$2004,"No",Detalle_Pagos!$B$5:$B$2004,">="&$B$3,Detalle_Pagos!$B$5:$B$2004,"<="&$B$4)) | O12: =IF(K12="","",COUNTIFS(Detalle_Pagos!$E$5:$E$2004,K12,Detalle_Pagos!$J$5:$J$2004,"No",Detalle_Pagos!$B$5:$B$2004,">="&$B$3,Detalle_Pagos!$B$5:$B$2004,"<="&$B$4)) | P12: =IF(K12="","",COUNTIFS(Detalle_Pagos!$E$5:$E$2004,K12,Detalle_Pagos!$J$5:$J$2004,"Si",Detalle_Pagos!$B$5:$B$2004,">="&$B$3,Detalle_Pagos!$B$5:$B$2004,"<="&$B$4)) | Q12: =IF(K12="","",O12*IFERROR(INDEX(Trabajadores!$D$5:$D$204,MATCH(K12,Trabajadores!$B$5:$B$204,0)),0)) | R12: =IF(K12="","",N12+Q12) | S12: =IF(K12="","",M12+N12) | T12: =IF(K12="","",S12+R12/100000+L12/100000000+(100000-ROW())/1000000000)
A13: =IFERROR(INDEX($K$8:$K$207,MATCH(LARGE($T$8:$T$207,ROWS($A$8:A13)),$T$8:$T$207,0)),"") | B13: =IFERROR(INDEX($L$8:$L$207,MATCH(LARGE($T$8:$T$207,ROWS($A$8:A13)),$T$8:$T$207,0)),"") | C13: =IFERROR(INDEX($M$8:$M$207,MATCH(LARGE($T$8:$T$207,ROWS($A$8:A13)),$T$8:$T$207,0)),"") | D13: =IFERROR(INDEX($N$8:$N$207,MATCH(LARGE($T$8:$T$207,ROWS($A$8:A13)),$T$8:$T$207,0)),"") | E13: =IFERROR(INDEX($O$8:$O$207,MATCH(LARGE($T$8:$T$207,ROWS($A$8:A13)),$T$8:$T$207,0)),"") | F13: =IFERROR(INDEX($P$8:$P$207,MATCH(LARGE($T$8:$T$207,ROWS($A$8:A13)),$T$8:$T$207,0)),"") | G13: =IFERROR(INDEX($Q$8:$Q$207,MATCH(LARGE($T$8:$T$207,ROWS($A$8:A13)),$T$8:$T$207,0)),"") | H13: =IFERROR(INDEX($R$8:$R$207,MATCH(LARGE($T$8:$T$207,ROWS($A$8:A13)),$T$8:$T$207,0)),"") | I13: =IFERROR(INDEX($S$8:$S$207,MATCH(LARGE($T$8:$T$207,ROWS($A$8:A13)),$T$8:$T$207,0)),"") | K13: =IF(Trabajadores!B10="","",Trabajadores!B10) | L13: =IF(K13="","",COUNTIFS(Detalle_Pagos!$E$5:$E$2004,K13,Detalle_Pagos!$B$5:$B$2004,">="&$B$3,Detalle_Pagos!$B$5:$B$2004,"<="&$B$4)) | M13: =IF(K13="","",SUMIFS(Detalle_Pagos!$I$5:$I$2004,Detalle_Pagos!$E$5:$E$2004,K13,Detalle_Pagos!$J$5:$J$2004,"Si",Detalle_Pagos!$B$5:$B$2004,">="&$B$3,Detalle_Pagos!$B$5:$B$2004,"<="&$B$4)) | N13: =IF(K13="","",SUMIFS(Detalle_Pagos!$I$5:$I$2004,Detalle_Pagos!$E$5:$E$2004,K13,Detalle_Pagos!$J$5:$J$2004,"No",Detalle_Pagos!$B$5:$B$2004,">="&$B$3,Detalle_Pagos!$B$5:$B$2004,"<="&$B$4)) | O13: =IF(K13="","",COUNTIFS(Detalle_Pagos!$E$5:$E$2004,K13,Detalle_Pagos!$J$5:$J$2004,"No",Detalle_Pagos!$B$5:$B$2004,">="&$B$3,Detalle_Pagos!$B$5:$B$2004,"<="&$B$4)) | P13: =IF(K13="","",COUNTIFS(Detalle_Pagos!$E$5:$E$2004,K13,Detalle_Pagos!$J$5:$J$2004,"Si",Detalle_Pagos!$B$5:$B$2004,">="&$B$3,Detalle_Pagos!$B$5:$B$2004,"<="&$B$4)) | Q13: =IF(K13="","",O13*IFERROR(INDEX(Trabajadores!$D$5:$D$204,MATCH(K13,Trabajadores!$B$5:$B$204,0)),0)) | R13: =IF(K13="","",N13+Q13) | S13: =IF(K13="","",M13+N13) | T13: =IF(K13="","",S13+R13/100000+L13/100000000+(100000-ROW())/1000000000)
A14: =IFERROR(INDEX($K$8:$K$207,MATCH(LARGE($T$8:$T$207,ROWS($A$8:A14)),$T$8:$T$207,0)),"") | B14: =IFERROR(INDEX($L$8:$L$207,MATCH(LARGE($T$8:$T$207,ROWS($A$8:A14)),$T$8:$T$207,0)),"") | C14: =IFERROR(INDEX($M$8:$M$207,MATCH(LARGE($T$8:$T$207,ROWS($A$8:A14)),$T$8:$T$207,0)),"") | D14: =IFERROR(INDEX($N$8:$N$207,MATCH(LARGE($T$8:$T$207,ROWS($A$8:A14)),$T$8:$T$207,0)),"") | E14: =IFERROR(INDEX($O$8:$O$207,MATCH(LARGE($T$8:$T$207,ROWS($A$8:A14)),$T$8:$T$207,0)),"") | F14: =IFERROR(INDEX($P$8:$P$207,MATCH(LARGE($T$8:$T$207,ROWS($A$8:A14)),$T$8:$T$207,0)),"") | G14: =IFERROR(INDEX($Q$8:$Q$207,MATCH(LARGE($T$8:$T$207,ROWS($A$8:A14)),$T$8:$T$207,0)),"") | H14: =IFERROR(INDEX($R$8:$R$207,MATCH(LARGE($T$8:$T$207,ROWS($A$8:A14)),$T$8:$T$207,0)),"") | I14: =IFERROR(INDEX($S$8:$S$207,MATCH(LARGE($T$8:$T$207,ROWS($A$8:A14)),$T$8:$T$207,0)),"") | K14: =IF(Trabajadores!B11="","",Trabajadores!B11) | L14: =IF(K14="","",COUNTIFS(Detalle_Pagos!$E$5:$E$2004,K14,Detalle_Pagos!$B$5:$B$2004,">="&$B$3,Detalle_Pagos!$B$5:$B$2004,"<="&$B$4)) | M14: =IF(K14="","",SUMIFS(Detalle_Pagos!$I$5:$I$2004,Detalle_Pagos!$E$5:$E$2004,K14,Detalle_Pagos!$J$5:$J$2004,"Si",Detalle_Pagos!$B$5:$B$2004,">="&$B$3,Detalle_Pagos!$B$5:$B$2004,"<="&$B$4)) | N14: =IF(K14="","",SUMIFS(Detalle_Pagos!$I$5:$I$2004,Detalle_Pagos!$E$5:$E$2004,K14,Detalle_Pagos!$J$5:$J$2004,"No",Detalle_Pagos!$B$5:$B$2004,">="&$B$3,Detalle_Pagos!$B$5:$B$2004,"<="&$B$4)) | O14: =IF(K14="","",COUNTIFS(Detalle_Pagos!$E$5:$E$2004,K14,Detalle_Pagos!$J$5:$J$2004,"No",Detalle_Pagos!$B$5:$B$2004,">="&$B$3,Detalle_Pagos!$B$5:$B$2004,"<="&$B$4)) | P14: =IF(K14="","",COUNTIFS(Detalle_Pagos!$E$5:$E$2004,K14,Detalle_Pagos!$J$5:$J$2004,"Si",Detalle_Pagos!$B$5:$B$2004,">="&$B$3,Detalle_Pagos!$B$5:$B$2004,"<="&$B$4)) | Q14: =IF(K14="","",O14*IFERROR(INDEX(Trabajadores!$D$5:$D$204,MATCH(K14,Trabajadores!$B$5:$B$204,0)),0)) | R14: =IF(K14="","",N14+Q14) | S14: =IF(K14="","",M14+N14) | T14: =IF(K14="","",S14+R14/100000+L14/100000000+(100000-ROW())/1000000000)
A15: =IFERROR(INDEX($K$8:$K$207,MATCH(LARGE($T$8:$T$207,ROWS($A$8:A15)),$T$8:$T$207,0)),"") | B15: =IFERROR(INDEX($L$8:$L$207,MATCH(LARGE($T$8:$T$207,ROWS($A$8:A15)),$T$8:$T$207,0)),"") | C15: =IFERROR(INDEX($M$8:$M$207,MATCH(LARGE($T$8:$T$207,ROWS($A$8:A15)),$T$8:$T$207,0)),"") | D15: =IFERROR(INDEX($N$8:$N$207,MATCH(LARGE($T$8:$T$207,ROWS($A$8:A15)),$T$8:$T$207,0)),"") | E15: =IFERROR(INDEX($O$8:$O$207,MATCH(LARGE($T$8:$T$207,ROWS($A$8:A15)),$T$8:$T$207,0)),"") | F15: =IFERROR(INDEX($P$8:$P$207,MATCH(LARGE($T$8:$T$207,ROWS($A$8:A15)),$T$8:$T$207,0)),"") | G15: =IFERROR(INDEX($Q$8:$Q$207,MATCH(LARGE($T$8:$T$207,ROWS($A$8:A15)),$T$8:$T$207,0)),"") | H15: =IFERROR(INDEX($R$8:$R$207,MATCH(LARGE($T$8:$T$207,ROWS($A$8:A15)),$T$8:$T$207,0)),"") | I15: =IFERROR(INDEX($S$8:$S$207,MATCH(LARGE($T$8:$T$207,ROWS($A$8:A15)),$T$8:$T$207,0)),"") | K15: =IF(Trabajadores!B12="","",Trabajadores!B12) | L15: =IF(K15="","",COUNTIFS(Detalle_Pagos!$E$5:$E$2004,K15,Detalle_Pagos!$B$5:$B$2004,">="&$B$3,Detalle_Pagos!$B$5:$B$2004,"<="&$B$4)) | M15: =IF(K15="","",SUMIFS(Detalle_Pagos!$I$5:$I$2004,Detalle_Pagos!$E$5:$E$2004,K15,Detalle_Pagos!$J$5:$J$2004,"Si",Detalle_Pagos!$B$5:$B$2004,">="&$B$3,Detalle_Pagos!$B$5:$B$2004,"<="&$B$4)) | N15: =IF(K15="","",SUMIFS(Detalle_Pagos!$I$5:$I$2004,Detalle_Pagos!$E$5:$E$2004,K15,Detalle_Pagos!$J$5:$J$2004,"No",Detalle_Pagos!$B$5:$B$2004,">="&$B$3,Detalle_Pagos!$B$5:$B$2004,"<="&$B$4)) | O15: =IF(K15="","",COUNTIFS(Detalle_Pagos!$E$5:$E$2004,K15,Detalle_Pagos!$J$5:$J$2004,"No",Detalle_Pagos!$B$5:$B$2004,">="&$B$3,Detalle_Pagos!$B$5:$B$2004,"<="&$B$4)) | P15: =IF(K15="","",COUNTIFS(Detalle_Pagos!$E$5:$E$2004,K15,Detalle_Pagos!$J$5:$J$2004,"Si",Detalle_Pagos!$B$5:$B$2004,">="&$B$3,Detalle_Pagos!$B$5:$B$2004,"<="&$B$4)) | Q15: =IF(K15="","",O15*IFERROR(INDEX(Trabajadores!$D$5:$D$204,MATCH(K15,Trabajadores!$B$5:$B$204,0)),0)) | R15: =IF(K15="","",N15+Q15) | S15: =IF(K15="","",M15+N15) | T15: =IF(K15="","",S15+R15/100000+L15/100000000+(100000-ROW())/1000000000)
A16: =IFERROR(INDEX($K$8:$K$207,MATCH(LARGE($T$8:$T$207,ROWS($A$8:A16)),$T$8:$T$207,0)),"") | B16: =IFERROR(INDEX($L$8:$L$207,MATCH(LARGE($T$8:$T$207,ROWS($A$8:A16)),$T$8:$T$207,0)),"") | C16: =IFERROR(INDEX($M$8:$M$207,MATCH(LARGE($T$8:$T$207,ROWS($A$8:A16)),$T$8:$T$207,0)),"") | D16: =IFERROR(INDEX($N$8:$N$207,MATCH(LARGE($T$8:$T$207,ROWS($A$8:A16)),$T$8:$T$207,0)),"") | E16: =IFERROR(INDEX($O$8:$O$207,MATCH(LARGE($T$8:$T$207,ROWS($A$8:A16)),$T$8:$T$207,0)),"") | F16: =IFERROR(INDEX($P$8:$P$207,MATCH(LARGE($T$8:$T$207,ROWS($A$8:A16)),$T$8:$T$207,0)),"") | G16: =IFERROR(INDEX($Q$8:$Q$207,MATCH(LARGE($T$8:$T$207,ROWS($A$8:A16)),$T$8:$T$207,0)),"") | H16: =IFERROR(INDEX($R$8:$R$207,MATCH(LARGE($T$8:$T$207,ROWS($A$8:A16)),$T$8:$T$207,0)),"") | I16: =IFERROR(INDEX($S$8:$S$207,MATCH(LARGE($T$8:$T$207,ROWS($A$8:A16)),$T$8:$T$207,0)),"") | K16: =IF(Trabajadores!B13="","",Trabajadores!B13) | L16: =IF(K16="","",COUNTIFS(Detalle_Pagos!$E$5:$E$2004,K16,Detalle_Pagos!$B$5:$B$2004,">="&$B$3,Detalle_Pagos!$B$5:$B$2004,"<="&$B$4)) | M16: =IF(K16="","",SUMIFS(Detalle_Pagos!$I$5:$I$2004,Detalle_Pagos!$E$5:$E$2004,K16,Detalle_Pagos!$J$5:$J$2004,"Si",Detalle_Pagos!$B$5:$B$2004,">="&$B$3,Detalle_Pagos!$B$5:$B$2004,"<="&$B$4)) | N16: =IF(K16="","",SUMIFS(Detalle_Pagos!$I$5:$I$2004,Detalle_Pagos!$E$5:$E$2004,K16,Detalle_Pagos!$J$5:$J$2004,"No",Detalle_Pagos!$B$5:$B$2004,">="&$B$3,Detalle_Pagos!$B$5:$B$2004,"<="&$B$4)) | O16: =IF(K16="","",COUNTIFS(Detalle_Pagos!$E$5:$E$2004,K16,Detalle_Pagos!$J$5:$J$2004,"No",Detalle_Pagos!$B$5:$B$2004,">="&$B$3,Detalle_Pagos!$B$5:$B$2004,"<="&$B$4)) | P16: =IF(K16="","",COUNTIFS(Detalle_Pagos!$E$5:$E$2004,K16,Detalle_Pagos!$J$5:$J$2004,"Si",Detalle_Pagos!$B$5:$B$2004,">="&$B$3,Detalle_Pagos!$B$5:$B$2004,"<="&$B$4)) | Q16: =IF(K16="","",O16*IFERROR(INDEX(Trabajadores!$D$5:$D$204,MATCH(K16,Trabajadores!$B$5:$B$204,0)),0)) | R16: =IF(K16="","",N16+Q16) | S16: =IF(K16="","",M16+N16) | T16: =IF(K16="","",S16+R16/100000+L16/100000000+(100000-ROW())/1000000000)
A17: =IFERROR(INDEX($K$8:$K$207,MATCH(LARGE($T$8:$T$207,ROWS($A$8:A17)),$T$8:$T$207,0)),"") | B17: =IFERROR(INDEX($L$8:$L$207,MATCH(LARGE($T$8:$T$207,ROWS($A$8:A17)),$T$8:$T$207,0)),"") | C17: =IFERROR(INDEX($M$8:$M$207,MATCH(LARGE($T$8:$T$207,ROWS($A$8:A17)),$T$8:$T$207,0)),"") | D17: =IFERROR(INDEX($N$8:$N$207,MATCH(LARGE($T$8:$T$207,ROWS($A$8:A17)),$T$8:$T$207,0)),"") | E17: =IFERROR(INDEX($O$8:$O$207,MATCH(LARGE($T$8:$T$207,ROWS($A$8:A17)),$T$8:$T$207,0)),"") | F17: =IFERROR(INDEX($P$8:$P$207,MATCH(LARGE($T$8:$T$207,ROWS($A$8:A17)),$T$8:$T$207,0)),"") | G17: =IFERROR(INDEX($Q$8:$Q$207,MATCH(LARGE($T$8:$T$207,ROWS($A$8:A17)),$T$8:$T$207,0)),"") | H17: =IFERROR(INDEX($R$8:$R$207,MATCH(LARGE($T$8:$T$207,ROWS($A$8:A17)),$T$8:$T$207,0)),"") | I17: =IFERROR(INDEX($S$8:$S$207,MATCH(LARGE($T$8:$T$207,ROWS($A$8:A17)),$T$8:$T$207,0)),"") | K17: =IF(Trabajadores!B14="","",Trabajadores!B14) | L17: =IF(K17="","",COUNTIFS(Detalle_Pagos!$E$5:$E$2004,K17,Detalle_Pagos!$B$5:$B$2004,">="&$B$3,Detalle_Pagos!$B$5:$B$2004,"<="&$B$4)) | M17: =IF(K17="","",SUMIFS(Detalle_Pagos!$I$5:$I$2004,Detalle_Pagos!$E$5:$E$2004,K17,Detalle_Pagos!$J$5:$J$2004,"Si",Detalle_Pagos!$B$5:$B$2004,">="&$B$3,Detalle_Pagos!$B$5:$B$2004,"<="&$B$4)) | N17: =IF(K17="","",SUMIFS(Detalle_Pagos!$I$5:$I$2004,Detalle_Pagos!$E$5:$E$2004,K17,Detalle_Pagos!$J$5:$J$2004,"No",Detalle_Pagos!$B$5:$B$2004,">="&$B$3,Detalle_Pagos!$B$5:$B$2004,"<="&$B$4)) | O17: =IF(K17="","",COUNTIFS(Detalle_Pagos!$E$5:$E$2004,K17,Detalle_Pagos!$J$5:$J$2004,"No",Detalle_Pagos!$B$5:$B$2004,">="&$B$3,Detalle_Pagos!$B$5:$B$2004,"<="&$B$4)) | P17: =IF(K17="","",COUNTIFS(Detalle_Pagos!$E$5:$E$2004,K17,Detalle_Pagos!$J$5:$J$2004,"Si",Detalle_Pagos!$B$5:$B$2004,">="&$B$3,Detalle_Pagos!$B$5:$B$2004,"<="&$B$4)) | Q17: =IF(K17="","",O17*IFERROR(INDEX(Trabajadores!$D$5:$D$204,MATCH(K17,Trabajadores!$B$5:$B$204,0)),0)) | R17: =IF(K17="","",N17+Q17) | S17: =IF(K17="","",M17+N17) | T17: =IF(K17="","",S17+R17/100000+L17/100000000+(100000-ROW())/1000000000)
A18: =IFERROR(INDEX($K$8:$K$207,MATCH(LARGE($T$8:$T$207,ROWS($A$8:A18)),$T$8:$T$207,0)),"") | B18: =IFERROR(INDEX($L$8:$L$207,MATCH(LARGE($T$8:$T$207,ROWS($A$8:A18)),$T$8:$T$207,0)),"") | C18: =IFERROR(INDEX($M$8:$M$207,MATCH(LARGE($T$8:$T$207,ROWS($A$8:A18)),$T$8:$T$207,0)),"") | D18: =IFERROR(INDEX($N$8:$N$207,MATCH(LARGE($T$8:$T$207,ROWS($A$8:A18)),$T$8:$T$207,0)),"") | E18: =IFERROR(INDEX($O$8:$O$207,MATCH(LARGE($T$8:$T$207,ROWS($A$8:A18)),$T$8:$T$207,0)),"") | F18: =IFERROR(INDEX($P$8:$P$207,MATCH(LARGE($T$8:$T$207,ROWS($A$8:A18)),$T$8:$T$207,0)),"") | G18: =IFERROR(INDEX($Q$8:$Q$207,MATCH(LARGE($T$8:$T$207,ROWS($A$8:A18)),$T$8:$T$207,0)),"") | H18: =IFERROR(INDEX($R$8:$R$207,MATCH(LARGE($T$8:$T$207,ROWS($A$8:A18)),$T$8:$T$207,0)),"") | I18: =IFERROR(INDEX($S$8:$S$207,MATCH(LARGE($T$8:$T$207,ROWS($A$8:A18)),$T$8:$T$207,0)),"") | K18: =IF(Trabajadores!B15="","",Trabajadores!B15) | L18: =IF(K18="","",COUNTIFS(Detalle_Pagos!$E$5:$E$2004,K18,Detalle_Pagos!$B$5:$B$2004,">="&$B$3,Detalle_Pagos!$B$5:$B$2004,"<="&$B$4)) | M18: =IF(K18="","",SUMIFS(Detalle_Pagos!$I$5:$I$2004,Detalle_Pagos!$E$5:$E$2004,K18,Detalle_Pagos!$J$5:$J$2004,"Si",Detalle_Pagos!$B$5:$B$2004,">="&$B$3,Detalle_Pagos!$B$5:$B$2004,"<="&$B$4)) | N18: =IF(K18="","",SUMIFS(Detalle_Pagos!$I$5:$I$2004,Detalle_Pagos!$E$5:$E$2004,K18,Detalle_Pagos!$J$5:$J$2004,"No",Detalle_Pagos!$B$5:$B$2004,">="&$B$3,Detalle_Pagos!$B$5:$B$2004,"<="&$B$4)) | O18: =IF(K18="","",COUNTIFS(Detalle_Pagos!$E$5:$E$2004,K18,Detalle_Pagos!$J$5:$J$2004,"No",Detalle_Pagos!$B$5:$B$2004,">="&$B$3,Detalle_Pagos!$B$5:$B$2004,"<="&$B$4)) | P18: =IF(K18="","",COUNTIFS(Detalle_Pagos!$E$5:$E$2004,K18,Detalle_Pagos!$J$5:$J$2004,"Si",Detalle_Pagos!$B$5:$B$2004,">="&$B$3,Detalle_Pagos!$B$5:$B$2004,"<="&$B$4)) | Q18: =IF(K18="","",O18*IFERROR(INDEX(Trabajadores!$D$5:$D$204,MATCH(K18,Trabajadores!$B$5:$B$204,0)),0)) | R18: =IF(K18="","",N18+Q18) | S18: =IF(K18="","",M18+N18) | T18: =IF(K18="","",S18+R18/100000+L18/100000000+(100000-ROW())/1000000000)
